<mujoco model="DexterousDynamos">
	<compiler angle="radian"/>
	<default>
		<geom rgba="1 1 1 1" type="mesh" friction="1 0.005 0.001" condim="3" margin="0.0005" contype="1" conaffinity="1"/>
		<joint type="hinge" limited="true" damping="0.1" armature="0.001" margin="0.01" frictionloss="0.001"/>
		<position ctrllimited="true" forcelimited="true" forcerange="-1 1" kp="2.0"/>
	</default>
	<asset>
		<mesh name="T-PP" file="assets/fusion_export_2024-11-20_17-56-34/T-PP.stl"/>
		<mesh name="M-DP" file="assets/fusion_export_2024-11-20_17-56-34/M-DP.stl"/>
		<mesh name="I-PP" file="assets/fusion_export_2024-11-20_17-56-34/I-PP.stl"/>
		<mesh name="T-AP_OUT" file="assets/fusion_export_2024-11-20_17-56-34/T-AP_OUT.stl"/>
		<mesh name="M-MP" file="assets/fusion_export_2024-11-20_17-56-34/M-MP.stl"/>
		<mesh name="T-DP" file="assets/fusion_export_2024-11-20_17-56-34/T-DP.stl"/>
		<mesh name="Carpals" file="assets/fusion_export_2024-11-20_17-56-34/Carpals.stl"/>
		<mesh name="P-PP" file="assets/fusion_export_2024-11-20_17-56-34/P-PP.stl"/>
		<mesh name="M-PP" file="assets/fusion_export_2024-11-20_17-56-34/M-PP.stl"/>
		<mesh name="T-Assembly" file="assets/fusion_export_2024-11-20_17-56-34/T-Assembly.stl"/>
		<mesh name="Tower_MK3" file="assets/fusion_export_2024-11-20_17-56-34/Tower_MK3.stl"/>
		<mesh name="M-Assembly" file="assets/fusion_export_2024-11-20_17-56-34/M-Assembly.stl"/>
		<mesh name="M-AP" file="assets/fusion_export_2024-11-20_17-56-34/M-AP.stl"/>
		<mesh name="P-Assembly" file="assets/fusion_export_2024-11-20_17-56-34/P-Assembly.stl"/>
		<mesh name="I-Assembly" file="assets/fusion_export_2024-11-20_17-56-34/I-Assembly.stl"/>
		<mesh name="T-AP" file="assets/fusion_export_2024-11-20_17-56-34/T-AP.stl"/>
	</asset>
	<worldbody>
		<body name="root" quat="1.0 0.0 0.0 0.0">
			<body name="cdd9b821" pos="0.0 0.0 0.0" quat="1.0 0.0 0.0 0.0">
				<body name="98f93b48" pos="0.19399999999999998 6.938893903894138e-20 0.001999999999999988" quat="0.7071067811865476 -4.7274285062999856e-17 0.7071067811865476 -1.783505146267928e-17">
					<body name="bf341e1a" pos="-0.029630565454705337 0.017900169042701267 -0.019110848098277396" quat="0.7678583570172355 0.46257424952983534 0.051416413707244375 -0.44019877286538506">
						<body name="e3eccde0" pos="-0.023000000000000548 -5.4643789493269423e-17 1.8962695996771473e-16" quat="0.7071067811865488 -0.7071067811865515 3.885780586188048e-15 -6.6058269965196814e-15">
							<body name="2fecb75f" pos="1.2679932492028603e-15 1.8284001096892923e-16 6.367317625235945e-16" quat="8.215650382226158e-15 -0.707106781186541 -1.3766765505351941e-14 0.7071067811865491">
								<body name="6c6b99c5" pos="2.9701718515240394e-16 0.00010000000000029603 0.029999999999999756" quat="0.4999999999999833 0.49999999999999906 0.5000000000000098 0.5000000000000073">
									<joint name="T-DP_6c6b99c5_joint" pos="-0.06830251934052653 0.05120816717868361 0.029379081265244203" axis="-0.32828818809840876 -0.7556498909230572 0.5667628321468021" range="-0.17453292519943295 1.5707963267948966"/>
									<geom mesh="T-DP"/>
								</body>
								<joint name="T-PP_2fecb75f_joint" pos="-0.050087635774369144 0.03235458332812764 0.014792772867936526" axis="0.3282881880984023 0.7556498909230484 -0.56676283214679" range="-0.17453292519943295 1.5707963267948966"/>
								<geom mesh="T-PP"/>
							</body>
							<joint name="T-AP_OUT_e3eccde0_joint" pos="-0.03612289170698183 0.017900169042700916 0.0036099364300006976" axis="0.7235884309551187 0.18450020807943793 0.6651161220467825" range="-0.7853981633974483 0.7853981633974483"/>
							<geom mesh="T-AP_OUT"/>
						</body>
						<joint name="T-AP_bf341e1a_joint" pos="-0.025829011812569965 0.007354881795979804 -0.00466369358369706" axis="-0.32828818809839133 -0.755649890923052 0.5667628321467939" range="-1.3089969389957472 1.3089969389957472"/>
						<geom mesh="T-AP"/>
					</body>
					<body name="0b72a183" pos="0.05301112400252541 0.008351108948623053 0.023436687892843765" quat="0.28402453039043624 0.10174485344927024 0.7017525569750015 -0.6453846912595069">
						<body name="109af8c7" pos="-6.115028372463487e-16 -4.771796924539009e-16 2.459926878362473e-17" quat="-0.17364817766693053 2.8727020762175925e-15 0.9848077530122068 4.440892098500626e-16">
							<body name="2bb10a06" pos="-1.695692197767329e-16 5.377642775528102e-17 0.030000000000000023" quat="0.9063077870366492 1.3322676295501878e-15 -0.42261826174069306 -4.996003610813204e-16">
								<body name="a35b8d3d" pos="0.0010000000000002526 -0.00010000000000018501 0.027999999999999928" quat="0.6161925953304929 0.3468525413772686 0.34685254137726895 0.6161925953304972">
									<joint name="M-DP_a35b8d3d_joint" pos="0.030017742190776645 0.058720339994727165 0.044932082643166726" axis="-0.5094095898464522 -0.1462531701689135 0.8480046462066138" range="0.0 1.3089969389957472"/>
									<geom mesh="M-DP"/>
								</body>
								<joint name="M-MP_2bb10a06_joint" pos="0.047376105680555884 0.03781208604148766 0.05175352923340909" axis="-0.5094095898464538 -0.1462531701689141 0.8480046462066171" range="0.0 2.0943951023931953"/>
								<geom mesh="M-MP"/>
							</body>
							<joint name="P-PP_109af8c7_joint" pos="0.046518797750248725 0.008351108948623034 0.046157472421122704" axis="-0.5094095898464626 -0.14625317016891595 0.8480046462066277" range="-0.17453292519943295 2.007128639793479"/>
							<geom mesh="P-PP"/>
						</body>
						<joint name="M-AP_0b72a183_joint" pos="0.03474022988337586 0.005128234212297336 0.038526062496381894" axis="0.2673007392290194 -0.9635967830889043 -0.005617332848729882" range="-0.6108652381980153 0.4363323129985824"/>
						<geom mesh="M-AP"/>
					</body>
					<body name="2f5c14d1" pos="0.02218588263493879 0.0016005340999633016 0.04476759599324914" quat="0.4777144171082598 0.4304593345768794 0.5609855267969318 -0.5213338044735973">
						<body name="eaab4f6b" pos="-6.407403765417645e-16 -2.0229250177436292e-16 1.015369822606096e-17" quat="-0.17364817766693066 -1.1102230246251565e-16 0.9848077530122064 -3.3306690738754696e-16">
							<body name="5d4a2b6f" pos="-2.0816681711721685e-17 6.591949208711867e-17 0.04800000000000035" quat="0.9999999999999993 -3.3306690738754696e-16 1.6653345369377348e-16 2.7755575615628914e-17">
								<body name="dbf0b71e" pos="0.0010000000000001822 -0.00010000000000024226 0.028000000000000004" quat="-0.5000000000000012 -0.5000000000000009 -0.5000000000000011 -0.49999999999999895">
									<joint name="M-DP_dbf0b71e_joint" pos="0.014158103315645841 0.07281231189780087 0.09401242785127" axis="-0.9810602621904032 -0.08583165117742816 0.17364817766693355" range="0.0 1.3089969389957472"/>
									<geom mesh="M-DP"/>
								</body>
								<joint name="M-MP_5d4a2b6f_joint" pos="0.014602303500007668 0.046782602352714704 0.08365593678553447" axis="-0.9810602621903993 -0.08583165117742886 0.17364817766693347" range="0.0 2.0943951023931953"/>
								<geom mesh="M-MP"/>
							</body>
							<joint name="M-PP_eaab4f6b_joint" pos="0.015693556382661705 0.0016005340999632656 0.06748838052152797" axis="-0.9810602621904083 -0.0858316511774296 0.1736481776669352" range="-0.17453292519943295 2.007128639793479"/>
							<geom mesh="M-PP"/>
						</body>
						<joint name="M-AP_2f5c14d1_joint" pos="0.013202537910140446 0.0013825982229840339 0.053307148878152015" axis="0.08715574274765676 -0.996194698091748 5.145107803428407e-17" range="-0.6108652381980153 0.4363323129985824"/>
						<geom mesh="M-AP"/>
					</body>
					<body name="ec3baf24" pos="-0.03217828353765348 0.002288273423863701 0.04574602043595696" quat="0.6360874680441195 0.6692319384003447 0.2443273021493679 -0.29635369922873295">
						<body name="a7e3761b" pos="1.4613854680890922e-15 1.4820702447904162e-16 4.0985948425987355e-17" quat="-0.25881904510251863 -5.689893001203927e-16 0.9659258262890653 4.996003610813204e-16">
							<body name="681cd8db" pos="1.448494102440634e-16 -5.898059818321144e-17 0.039999999999999945" quat="0.976296007119934 3.885780586188048e-16 -0.2164396139381023 5.828670879282072e-16">
								<body name="5e80261b" pos="0.0009999999999998508 -0.0001000000000000098 0.027999999999999838" quat="0.5633249626000165 0.4273932457487988 0.4273932457488024 0.5633249626000154">
									<joint name="M-DP_5e80261b_joint" pos="-0.04983242498150006 0.06566955917025467 0.0859929398109383" axis="-0.7040370164189176 0.07139380484327053 -0.7065654988335821" range="0.0 1.3089969389957472"/>
									<geom mesh="M-DP"/>
								</body>
								<joint name="M-MP_681cd8db_joint" pos="-0.049796460350306854 0.03779727965703099 0.08314079302614225" axis="-0.7040370164189168 0.07139380484327015 -0.7065654988335829" range="0.0 2.0943951023931953"/>
								<geom mesh="M-MP"/>
							</body>
							<joint name="I-PP_a7e3761b_joint" pos="-0.03867060978992938 0.0022882734238636225 0.06846680496423421" axis="-0.7040370164189139 0.07139380484326988 -0.7065654988335798" range="-0.17453292519943295 2.007128639793479"/>
							<geom mesh="I-PP"/>
						</body>
						<joint name="M-AP_ec3baf24_joint" pos="-0.028519224543847112 0.0015684105070723161 0.058279009571380665" axis="-0.08583165117743209 -0.9961946980917432 -0.015134435901338936" range="-0.6108652381980153 0.4363323129985824"/>
						<geom mesh="M-AP"/>
					</body>
					<body name="83dd5c53" pos="-0.00221718216200527 -7.028457889201714e-18 0.05330374746807648" quat="0.5213338044735961 0.5213338044735965 0.47771441710826157 -0.4777144171082609">
						<body name="404c48f7" pos="-2.315472412023369e-16 6.030880494617334e-17 -4.930380657631324e-32" quat="-0.17364817766693078 3.885780586188048e-16 0.9848077530122079 1.6653345369377348e-16">
							<body name="284f0eba" pos="3.122502256758253e-17 1.0408340855860843e-17 0.048000000000000334" quat="0.9999999999999993 1.1102230246251565e-16 -8.049116928532385e-16 -1.1102230246251565e-16">
								<body name="932d4bbb" pos="0.000999999999999928 -9.999999999989184e-05 0.02799999999999977" quat="-0.5000000000000004 -0.5000000000000017 -0.5000000000000009 -0.5000000000000007">
									<joint name="M-DP_932d4bbb_joint" pos="-0.011056893514192936 0.07107461903640344 0.10285526646306012" axis="-0.996194698091747 8.81290171736394e-16 -0.08715574274765532" range="0.0 1.3089969389957472"/>
									<geom mesh="M-DP"/>
								</body>
								<joint name="M-MP_284f0eba_joint" pos="-0.010140341356340177 0.04510524579772388 0.09237902736059236" axis="-0.9961946980917431 1.0498100235067102e-15 -0.08715574274765509" range="0.0 2.0943951023931953"/>
								<geom mesh="M-MP"/>
							</body>
							<joint name="M-PP_404c48f7_joint" pos="-0.008709508414282235 -3.804849346849189e-18 0.07602453199635492" axis="-0.9961946980917443 1.092875789865389e-15 -0.087155742747655" range="-0.17453292519943295 2.007128639793479"/>
							<geom mesh="M-PP"/>
						</body>
						<joint name="M-AP_83dd5c53_joint" pos="-0.007454465718716002 5.551115123125788e-19 0.061679328343833634" axis="-9.89388692501647e-16 -0.9999999999999998 1.474514954580286e-16" range="-0.4363323129985824 0.6108652381980153"/>
						<geom mesh="M-AP"/>
					</body>
					<joint name="Carpals_98f93b48_joint" pos="-0.0044923262522769325 4.048056159492783e-18 -0.02727921547172185" axis="0.9999999999999996 -1.0755285551056194e-15 4.0245584642661934e-16" range="-1.3962634015954636 1.3962634015954636"/>
					<geom mesh="Carpals"/>
				</body>
				<geom mesh="Tower_MK3"/>
			</body>
		</body>
	</worldbody>
	<actuator>
		<position name="Carpals_98f93b48_joint_actuator" joint="Carpals_98f93b48_joint" ctrlrange="-1.3962634015954636 1.3962634015954636"/>
		<position name="M-AP_83dd5c53_joint_actuator" joint="M-AP_83dd5c53_joint" ctrlrange="-0.4363323129985824 0.6108652381980153"/>
		<position name="M-PP_404c48f7_joint_actuator" joint="M-PP_404c48f7_joint" ctrlrange="-0.17453292519943295 2.007128639793479"/>
		<position name="M-MP_284f0eba_joint_actuator" joint="M-MP_284f0eba_joint" ctrlrange="0.0 2.0943951023931953"/>
		<position name="M-DP_932d4bbb_joint_actuator" joint="M-DP_932d4bbb_joint" ctrlrange="0.0 1.3089969389957472"/>
		<position name="M-AP_ec3baf24_joint_actuator" joint="M-AP_ec3baf24_joint" ctrlrange="-0.6108652381980153 0.4363323129985824"/>
		<position name="I-PP_a7e3761b_joint_actuator" joint="I-PP_a7e3761b_joint" ctrlrange="-0.17453292519943295 2.007128639793479"/>
		<position name="M-MP_681cd8db_joint_actuator" joint="M-MP_681cd8db_joint" ctrlrange="0.0 2.0943951023931953"/>
		<position name="M-DP_5e80261b_joint_actuator" joint="M-DP_5e80261b_joint" ctrlrange="0.0 1.3089969389957472"/>
		<position name="M-AP_2f5c14d1_joint_actuator" joint="M-AP_2f5c14d1_joint" ctrlrange="-0.6108652381980153 0.4363323129985824"/>
		<position name="M-PP_eaab4f6b_joint_actuator" joint="M-PP_eaab4f6b_joint" ctrlrange="-0.17453292519943295 2.007128639793479"/>
		<position name="M-MP_5d4a2b6f_joint_actuator" joint="M-MP_5d4a2b6f_joint" ctrlrange="0.0 2.0943951023931953"/>
		<position name="M-DP_dbf0b71e_joint_actuator" joint="M-DP_dbf0b71e_joint" ctrlrange="0.0 1.3089969389957472"/>
		<position name="M-AP_0b72a183_joint_actuator" joint="M-AP_0b72a183_joint" ctrlrange="-0.6108652381980153 0.4363323129985824"/>
		<position name="P-PP_109af8c7_joint_actuator" joint="P-PP_109af8c7_joint" ctrlrange="-0.17453292519943295 2.007128639793479"/>
		<position name="M-MP_2bb10a06_joint_actuator" joint="M-MP_2bb10a06_joint" ctrlrange="0.0 2.0943951023931953"/>
		<position name="M-DP_a35b8d3d_joint_actuator" joint="M-DP_a35b8d3d_joint" ctrlrange="0.0 1.3089969389957472"/>
		<position name="T-AP_bf341e1a_joint_actuator" joint="T-AP_bf341e1a_joint" ctrlrange="-1.3089969389957472 1.3089969389957472"/>
		<position name="T-AP_OUT_e3eccde0_joint_actuator" joint="T-AP_OUT_e3eccde0_joint" ctrlrange="-0.7853981633974483 0.7853981633974483"/>
		<position name="T-PP_2fecb75f_joint_actuator" joint="T-PP_2fecb75f_joint" ctrlrange="-0.17453292519943295 1.5707963267948966"/>
		<position name="T-DP_6c6b99c5_joint_actuator" joint="T-DP_6c6b99c5_joint" ctrlrange="-0.17453292519943295 1.5707963267948966"/>
	</actuator>
	<contact>
		<exclude body1="root" body2="cdd9b821"/>
		<exclude body1="cdd9b821" body2="98f93b48"/>
		<exclude body1="98f93b48" body2="83dd5c53"/>
		<exclude body1="83dd5c53" body2="404c48f7"/>
		<exclude body1="404c48f7" body2="284f0eba"/>
		<exclude body1="284f0eba" body2="932d4bbb"/>
		<exclude body1="98f93b48" body2="ec3baf24"/>
		<exclude body1="ec3baf24" body2="a7e3761b"/>
		<exclude body1="a7e3761b" body2="681cd8db"/>
		<exclude body1="681cd8db" body2="5e80261b"/>
		<exclude body1="98f93b48" body2="2f5c14d1"/>
		<exclude body1="2f5c14d1" body2="eaab4f6b"/>
		<exclude body1="eaab4f6b" body2="5d4a2b6f"/>
		<exclude body1="5d4a2b6f" body2="dbf0b71e"/>
		<exclude body1="98f93b48" body2="0b72a183"/>
		<exclude body1="0b72a183" body2="109af8c7"/>
		<exclude body1="109af8c7" body2="2bb10a06"/>
		<exclude body1="2bb10a06" body2="a35b8d3d"/>
		<exclude body1="98f93b48" body2="bf341e1a"/>
		<exclude body1="bf341e1a" body2="e3eccde0"/>
		<exclude body1="e3eccde0" body2="2fecb75f"/>
		<exclude body1="2fecb75f" body2="6c6b99c5"/>
	</contact>
	<equality>
	</equality>
</mujoco>