<mujoco model="DexterousDynamos">
	<compiler angle="radian"/>
	<default>
		<geom rgba="1 1 1 1" type="mesh" friction="1 0.005 0.001" condim="3" margin="0.0005" contype="1" conaffinity="1"/>
		<joint type="hinge" limited="true" damping="0.1" armature="0.001" margin="0.01" frictionloss="0.001"/>
		<position ctrllimited="true" forcelimited="true" forcerange="-1 1" kp="2.0"/>
		<mesh scale="0.001 0.001 0.001"/>
	</default>
	<asset>
		<mesh name="T-PP" file="assets/fusion_export_2024-11-20_17-56-34/T-PP.stl"/>
		<mesh name="M-DP" file="assets/fusion_export_2024-11-20_17-56-34/M-DP.stl"/>
		<mesh name="I-PP" file="assets/fusion_export_2024-11-20_17-56-34/I-PP.stl"/>
		<mesh name="T-AP_OUT" file="assets/fusion_export_2024-11-20_17-56-34/T-AP_OUT.stl"/>
		<mesh name="M-MP" file="assets/fusion_export_2024-11-20_17-56-34/M-MP.stl"/>
		<mesh name="T-DP" file="assets/fusion_export_2024-11-20_17-56-34/T-DP.stl"/>
		<mesh name="Carpals" file="assets/fusion_export_2024-11-20_17-56-34/Carpals.stl"/>
		<mesh name="P-PP" file="assets/fusion_export_2024-11-20_17-56-34/P-PP.stl"/>
		<mesh name="M-PP" file="assets/fusion_export_2024-11-20_17-56-34/M-PP.stl"/>
		<mesh name="T-Assembly" file="assets/fusion_export_2024-11-20_17-56-34/T-Assembly.stl"/>
		<mesh name="Tower_MK3" file="assets/fusion_export_2024-11-20_17-56-34/Tower_MK3.stl"/>
		<mesh name="M-Assembly" file="assets/fusion_export_2024-11-20_17-56-34/M-Assembly.stl"/>
		<mesh name="M-AP" file="assets/fusion_export_2024-11-20_17-56-34/M-AP.stl"/>
		<mesh name="P-Assembly" file="assets/fusion_export_2024-11-20_17-56-34/P-Assembly.stl"/>
		<mesh name="I-Assembly" file="assets/fusion_export_2024-11-20_17-56-34/I-Assembly.stl"/>
		<mesh name="T-AP" file="assets/fusion_export_2024-11-20_17-56-34/T-AP.stl"/>
	</asset>
	<worldbody>
		<body name="root" quat="1.0 0.0 0.0 0.0">
			<body name="Tower_MK3_cdd9b821" pos="0.0 0.0 0.0" quat="1.0 0.0 0.0 0.0">
				<body name="Carpals_98f93b48" pos="0.19399999999999998 6.938893903894138e-20 0.001999999999999988" quat="0.7071067811865476 -4.7274285062999856e-17 0.7071067811865476 -1.783505146267928e-17">
					<body name="T-AP_bf341e1a" pos="-0.029630565454705337 0.017900169042701267 -0.019110848098277396" quat="0.7678583570172355 0.46257424952983534 0.051416413707244375 -0.44019877286538506">
						<body name="T-AP_OUT_e3eccde0" pos="-0.023000000000000548 -5.4643789493269423e-17 1.8962695996771473e-16" quat="0.7071067811865488 -0.7071067811865515 3.885780586188048e-15 -6.6058269965196814e-15">
							<body name="T-PP_2fecb75f" pos="1.2679932492028603e-15 1.8284001096892923e-16 6.367317625235945e-16" quat="8.215650382226158e-15 -0.707106781186541 -1.3766765505351941e-14 0.7071067811865491">
								<body name="T-DP_6c6b99c5" pos="2.9701718515240394e-16 0.00010000000000029603 0.029999999999999756" quat="0.4999999999999833 0.49999999999999906 0.5000000000000098 0.5000000000000073">
									<joint name="T-DP_6c6b99c5_joint" pos="-0.00010000000000001411 -2.9144709649125966e-17 9.046227173381202e-17" axis="1.0000000000000104 1.9984014443252818e-15 1.2587153541687712e-14" range="-0.17453292519943295 1.5707963267948966"/>
									<geom mesh="T-DP"/>
								</body>
								<joint name="T-PP_2fecb75f_joint" pos="1.0439948562885094e-18 1.775707855051623e-18 1.3493639973322685e-16" axis="2.0511370379949767e-14 -0.999999999999994 -1.1157741397482823e-14" range="-0.17453292519943295 1.5707963267948966"/>
								<geom mesh="T-PP"/>
							</body>
							<joint name="T-AP_OUT_e3eccde0_joint" pos="0.023000000000001186 1.734723475976807e-16 6.067195357228883e-16" axis="-1.514760539222948e-14 -6.2450045135165055e-15 0.9999999999999984" range="-0.7853981633974483 0.7853981633974483"/>
							<geom mesh="T-AP_OUT"/>
						</body>
						<joint name="T-AP_bf341e1a_joint" pos="0.016900000000000373 1.2923689896027213e-16 -9.999999999982278e-05" axis="-1.1102230246251565e-16 3.1086244689504383e-15 0.999999999999996" range="-1.3089969389957472 1.3089969389957472"/>
						<geom mesh="T-AP"/>
					</body>
					<body name="M-AP_0b72a183" pos="0.05301112400252541 0.008351108948623053 0.023436687892843765" quat="0.28402453039043624 0.10174485344927024 0.7017525569750015 -0.6453846912595069">
						<body name="P-PP_109af8c7" pos="-6.115028372463487e-16 -4.771796924539009e-16 2.459926878362473e-17" quat="-0.17364817766693053 2.8727020762175925e-15 0.9848077530122068 4.440892098500626e-16">
							<body name="M-MP_2bb10a06" pos="-1.695692197767329e-16 5.377642775528102e-17 0.030000000000000023" quat="0.9063077870366492 1.3322676295501878e-15 -0.42261826174069306 -4.996003610813204e-16">
								<body name="M-DP_a35b8d3d" pos="0.0010000000000002526 -0.00010000000000018501 0.027999999999999928" quat="0.6161925953304929 0.3468525413772686 0.34685254137726895 0.6161925953304972">
									<joint name="M-DP_a35b8d3d_joint" pos="0.0001000000000000123 -5.194683658921173e-17 -1.4280636677528602e-16" axis="-1.0 5.412337245047638e-15 8.326672684688674e-16" range="0.0 1.3089969389957472"/>
									<geom mesh="M-DP"/>
								</body>
								<joint name="M-MP_2bb10a06_joint" pos="-5.434058682218112e-18 4.403694540190368e-17 -9.985982225654608e-17" axis="3.885780586188048e-15 -1.000000000000006 2.1649348980190553e-15" range="0.0 2.0943951023931953"/>
								<geom mesh="M-MP"/>
							</body>
							<joint name="P-PP_109af8c7_joint" pos="2.7520274902977274e-17 8.001033312533638e-18 3.839623666002223e-19" axis="-9.159339953157541e-16 -1.0000000000000127 1.3322676295501878e-15" range="-0.17453292519943295 2.007128639793479"/>
							<geom mesh="P-PP"/>
						</body>
						<joint name="M-AP_0b72a183_joint" pos="0.014399999999999625 -3.389215991189687e-16 2.905661822261152e-17" axis="1.8596235662471372e-15 5.551115123125783e-17 0.9999999999999962" range="-0.6108652381980153 0.4363323129985824"/>
						<geom mesh="M-AP"/>
					</body>
					<body name="M-AP_2f5c14d1" pos="0.02218588263493879 0.0016005340999633016 0.04476759599324914" quat="0.4777144171082598 0.4304593345768794 0.5609855267969318 -0.5213338044735973">
						<body name="M-PP_eaab4f6b" pos="-6.407403765417645e-16 -2.0229250177436292e-16 1.015369822606096e-17" quat="-0.17364817766693066 -1.1102230246251565e-16 0.9848077530122064 -3.3306690738754696e-16">
							<body name="M-MP_5d4a2b6f" pos="-2.0816681711721685e-17 6.591949208711867e-17 0.04800000000000035" quat="0.9999999999999993 -3.3306690738754696e-16 1.6653345369377348e-16 2.7755575615628914e-17">
								<body name="M-DP_dbf0b71e" pos="0.0010000000000001822 -0.00010000000000024226 0.028000000000000004" quat="-0.5000000000000012 -0.5000000000000009 -0.5000000000000011 -0.49999999999999895">
									<joint name="M-DP_dbf0b71e_joint" pos="0.00010000000000002212 -1.0434683580520451e-16 -4.8352875794011735e-17" axis="-0.9999999999999987 -6.661338147750939e-16 3.74353326115795e-15" range="0.0 1.3089969389957472"/>
									<geom mesh="M-DP"/>
								</body>
								<joint name="M-MP_5d4a2b6f_joint" pos="4.167064900386223e-17 1.3133320452668772e-17 -1.489202278821702e-16" axis="2.3592239273284576e-15 -0.9999999999999971 1.1102230246251565e-15" range="0.0 2.0943951023931953"/>
								<geom mesh="M-MP"/>
							</body>
							<joint name="M-PP_eaab4f6b_joint" pos="-2.7485630299731758e-17 1.7137569499700596e-18 -6.004104113240901e-18" axis="2.609024107869118e-15 -1.0000000000000049 1.6653345369377348e-15" range="-0.17453292519943295 2.007128639793479"/>
							<geom mesh="M-PP"/>
						</body>
						<joint name="M-AP_2f5c14d1_joint" pos="0.014399999999999536 -1.1362438767648086e-16 -9.974659986866641e-18" axis="-1.609823385706477e-15 1.6653345369377348e-16 1.000000000000002" range="-0.6108652381980153 0.4363323129985824"/>
						<geom mesh="M-AP"/>
					</body>
					<body name="M-AP_ec3baf24" pos="-0.03217828353765348 0.002288273423863701 0.04574602043595696" quat="0.6360874680441195 0.6692319384003447 0.2443273021493679 -0.29635369922873295">
						<body name="I-PP_a7e3761b" pos="1.4613854680890922e-15 1.4820702447904162e-16 4.0985948425987355e-17" quat="-0.25881904510251863 -5.689893001203927e-16 0.9659258262890653 4.996003610813204e-16">
							<body name="M-MP_681cd8db" pos="1.448494102440634e-16 -5.898059818321144e-17 0.039999999999999945" quat="0.976296007119934 3.885780586188048e-16 -0.2164396139381023 5.828670879282072e-16">
								<body name="M-DP_5e80261b" pos="0.0009999999999998508 -0.0001000000000000098 0.027999999999999838" quat="0.5633249626000165 0.4273932457487988 0.4273932457488024 0.5633249626000154">
									<joint name="M-DP_5e80261b_joint" pos="9.999999999995173e-05 3.3861836132385165e-17 8.135169123226317e-17" axis="-0.9999999999999923 -3.344546861683284e-15 -4.961309141293668e-15" range="0.0 1.3089969389957472"/>
									<geom mesh="M-DP"/>
								</body>
								<joint name="M-MP_681cd8db_joint" pos="-3.1857056024627384e-17 -3.437063856744217e-17 6.596930344354583e-17" axis="-3.3584246494910985e-15 -1.0000000000000007 5.551115123125783e-17" range="0.0 2.0943951023931953"/>
								<geom mesh="M-MP"/>
							</body>
							<joint name="I-PP_a7e3761b_joint" pos="2.4758990153200526e-17 -1.0014045726209169e-17 1.6276076731429818e-17" axis="-1.3877787807814457e-15 -0.9999999999999978 -1.6653345369377348e-15" range="-0.17453292519943295 2.007128639793479"/>
							<geom mesh="I-PP"/>
						</body>
						<joint name="M-AP_ec3baf24_joint" pos="0.014400000000001228 2.1510571102112408e-16 2.168404344971009e-17" axis="6.106226635438361e-16 -9.992007221626409e-16 0.9999999999999934" range="-0.6108652381980153 0.4363323129985824"/>
						<geom mesh="M-AP"/>
					</body>
					<body name="M-AP_83dd5c53" pos="-0.00221718216200527 -7.028457889201714e-18 0.05330374746807648" quat="0.5213338044735961 0.5213338044735965 0.47771441710826157 -0.4777144171082609">
						<body name="M-PP_404c48f7" pos="-2.315472412023369e-16 6.030880494617334e-17 -4.930380657631324e-32" quat="-0.17364817766693078 3.885780586188048e-16 0.9848077530122079 1.6653345369377348e-16">
							<body name="M-MP_284f0eba" pos="3.122502256758253e-17 1.0408340855860843e-17 0.048000000000000334" quat="0.9999999999999993 1.1102230246251565e-16 -8.049116928532385e-16 -1.1102230246251565e-16">
								<body name="M-DP_932d4bbb" pos="0.000999999999999928 -9.999999999989184e-05 0.02799999999999977" quat="-0.5000000000000004 -0.5000000000000017 -0.5000000000000009 -0.5000000000000007">
									<joint name="M-DP_932d4bbb_joint" pos="0.00010000000000004635 5.552915068138698e-17 -9.090450234161757e-17" axis="-0.9999999999999996 1.4649739754624136e-15 1.5874888209532756e-15" range="0.0 1.3089969389957472"/>
									<geom mesh="M-DP"/>
								</body>
								<joint name="M-MP_284f0eba_joint" pos="-4.2637153682423176e-17 2.6959021792028595e-17 2.8786645134404564e-17" axis="9.159339953157541e-16 -0.9999999999999994 3.885780586188048e-16" range="0.0 2.0943951023931953"/>
								<geom mesh="M-MP"/>
							</body>
							<joint name="M-PP_404c48f7_joint" pos="2.742586910455838e-17 6.909354787454898e-19 5.933163900404158e-18" axis="5.828670879282072e-16 -0.9999999999999993 4.996003610813204e-16" range="-0.17453292519943295 2.007128639793479"/>
							<geom mesh="M-PP"/>
						</body>
						<joint name="M-AP_83dd5c53_joint" pos="0.014399999999999899 2.2551405187698492e-17 1.0842021724855044e-17" axis="-9.43689570931383e-16 -2.220446049250313e-16 1.0000000000000004" range="-0.4363323129985824 0.6108652381980153"/>
						<geom mesh="M-AP"/>
					</body>
					<joint name="Carpals_98f93b48_joint" pos="0.002000000000000015 6.244492405129371e-18 -0.05000000000000003" axis="0.9999999999999996 9.207850675172913e-17 -1.3936265188470615e-16" range="-1.3962634015954636 1.3962634015954636"/>
					<geom mesh="Carpals"/>
				</body>
				<geom mesh="Tower_MK3"/>
			</body>
		</body>
	</worldbody>
	<actuator>
		<position name="Carpals_98f93b48_joint_actuator" joint="Carpals_98f93b48_joint" ctrlrange="-1.3962634015954636 1.3962634015954636"/>
		<position name="M-AP_83dd5c53_joint_actuator" joint="M-AP_83dd5c53_joint" ctrlrange="-0.4363323129985824 0.6108652381980153"/>
		<position name="M-PP_404c48f7_joint_actuator" joint="M-PP_404c48f7_joint" ctrlrange="-0.17453292519943295 2.007128639793479"/>
		<position name="M-MP_284f0eba_joint_actuator" joint="M-MP_284f0eba_joint" ctrlrange="0.0 2.0943951023931953"/>
		<position name="M-AP_ec3baf24_joint_actuator" joint="M-AP_ec3baf24_joint" ctrlrange="-0.6108652381980153 0.4363323129985824"/>
		<position name="I-PP_a7e3761b_joint_actuator" joint="I-PP_a7e3761b_joint" ctrlrange="-0.17453292519943295 2.007128639793479"/>
		<position name="M-MP_681cd8db_joint_actuator" joint="M-MP_681cd8db_joint" ctrlrange="0.0 2.0943951023931953"/>
		<position name="M-AP_2f5c14d1_joint_actuator" joint="M-AP_2f5c14d1_joint" ctrlrange="-0.6108652381980153 0.4363323129985824"/>
		<position name="M-PP_eaab4f6b_joint_actuator" joint="M-PP_eaab4f6b_joint" ctrlrange="-0.17453292519943295 2.007128639793479"/>
		<position name="M-MP_5d4a2b6f_joint_actuator" joint="M-MP_5d4a2b6f_joint" ctrlrange="0.0 2.0943951023931953"/>
		<position name="M-AP_0b72a183_joint_actuator" joint="M-AP_0b72a183_joint" ctrlrange="-0.6108652381980153 0.4363323129985824"/>
		<position name="P-PP_109af8c7_joint_actuator" joint="P-PP_109af8c7_joint" ctrlrange="-0.17453292519943295 2.007128639793479"/>
		<position name="M-MP_2bb10a06_joint_actuator" joint="M-MP_2bb10a06_joint" ctrlrange="0.0 2.0943951023931953"/>
		<position name="T-AP_bf341e1a_joint_actuator" joint="T-AP_bf341e1a_joint" ctrlrange="-1.3089969389957472 1.3089969389957472"/>
		<position name="T-AP_OUT_e3eccde0_joint_actuator" joint="T-AP_OUT_e3eccde0_joint" ctrlrange="-0.7853981633974483 0.7853981633974483"/>
		<position name="T-PP_2fecb75f_joint_actuator" joint="T-PP_2fecb75f_joint" ctrlrange="-0.17453292519943295 1.5707963267948966"/>
	</actuator>
	<contact>
		<exclude body1="root" body2="Tower_MK3_cdd9b821"/>
		<exclude body1="Tower_MK3_cdd9b821" body2="Carpals_98f93b48"/>
		<exclude body1="Carpals_98f93b48" body2="M-AP_83dd5c53"/>
		<exclude body1="M-AP_83dd5c53" body2="M-PP_404c48f7"/>
		<exclude body1="M-PP_404c48f7" body2="M-MP_284f0eba"/>
		<exclude body1="M-MP_284f0eba" body2="M-DP_932d4bbb"/>
		<exclude body1="Carpals_98f93b48" body2="M-AP_ec3baf24"/>
		<exclude body1="M-AP_ec3baf24" body2="I-PP_a7e3761b"/>
		<exclude body1="I-PP_a7e3761b" body2="M-MP_681cd8db"/>
		<exclude body1="M-MP_681cd8db" body2="M-DP_5e80261b"/>
		<exclude body1="Carpals_98f93b48" body2="M-AP_2f5c14d1"/>
		<exclude body1="M-AP_2f5c14d1" body2="M-PP_eaab4f6b"/>
		<exclude body1="M-PP_eaab4f6b" body2="M-MP_5d4a2b6f"/>
		<exclude body1="M-MP_5d4a2b6f" body2="M-DP_dbf0b71e"/>
		<exclude body1="Carpals_98f93b48" body2="M-AP_0b72a183"/>
		<exclude body1="M-AP_0b72a183" body2="P-PP_109af8c7"/>
		<exclude body1="P-PP_109af8c7" body2="M-MP_2bb10a06"/>
		<exclude body1="M-MP_2bb10a06" body2="M-DP_a35b8d3d"/>
		<exclude body1="Carpals_98f93b48" body2="T-AP_bf341e1a"/>
		<exclude body1="T-AP_bf341e1a" body2="T-AP_OUT_e3eccde0"/>
		<exclude body1="T-AP_OUT_e3eccde0" body2="T-PP_2fecb75f"/>
		<exclude body1="T-PP_2fecb75f" body2="T-DP_6c6b99c5"/>
	</contact>
	<equality>
	<joint joint1="M-DP_932d4bbb_joint" joint2="M-MP_284f0eba_joint" polycoef="0 0.5833333333333334 0 0 0"/>
	<joint joint1="M-DP_5e80261b_joint" joint2="M-MP_681cd8db_joint" polycoef="0 0.5833333333333334 0 0 0"/>
	<joint joint1="M-DP_dbf0b71e_joint" joint2="M-MP_5d4a2b6f_joint" polycoef="0 0.5833333333333334 0 0 0"/>
	<joint joint1="M-DP_a35b8d3d_joint" joint2="M-MP_2bb10a06_joint" polycoef="0 0.5833333333333334 0 0 0"/>
	<joint joint1="T-DP_6c6b99c5_joint" joint2="T-PP_2fecb75f_joint" polycoef="0 -0.5833333333333334 0 0 0"/>
	</equality>
</mujoco>