<mujoco model="DexterousDynamos">
	<compiler angle="radian"/>
	<default>
		<geom rgba="1 1 1 1" type="mesh" friction="1 0.005 0.001" condim="3" margin="0.0005" contype="1" conaffinity="1"/>
		<joint type="hinge" limited="true" damping="0.1" armature="0.001" margin="0.01" frictionloss="0.001"/>
		<position ctrllimited="true" forcelimited="true" forcerange="-1 1" kp="2.0"/>
		<mesh scale="0.001 0.001 0.001"/>
	</default>
	<asset>
		<mesh name="M-PP" file="assets/fusion_export_2024-11-21_14-46-37/M-PP.stl"/>
		<mesh name="I-Assembly" file="assets/fusion_export_2024-11-21_14-46-37/I-Assembly.stl"/>
		<mesh name="M-Assembly" file="assets/fusion_export_2024-11-21_14-46-37/M-Assembly.stl"/>
		<mesh name="P-Assembly" file="assets/fusion_export_2024-11-21_14-46-37/P-Assembly.stl"/>
		<mesh name="P-PP" file="assets/fusion_export_2024-11-21_14-46-37/P-PP.stl"/>
		<mesh name="Carpals" file="assets/fusion_export_2024-11-21_14-46-37/Carpals.stl"/>
		<mesh name="M-MP" file="assets/fusion_export_2024-11-21_14-46-37/M-MP.stl"/>
		<mesh name="T-Assembly" file="assets/fusion_export_2024-11-21_14-46-37/T-Assembly.stl"/>
		<mesh name="T-DP" file="assets/fusion_export_2024-11-21_14-46-37/T-DP.stl"/>
		<mesh name="Tower_MK3" file="assets/fusion_export_2024-11-21_14-46-37/Tower_MK3.stl"/>
		<mesh name="M-AP" file="assets/fusion_export_2024-11-21_14-46-37/M-AP.stl"/>
		<mesh name="T-AP_OUT" file="assets/fusion_export_2024-11-21_14-46-37/T-AP_OUT.stl"/>
		<mesh name="M-DP" file="assets/fusion_export_2024-11-21_14-46-37/M-DP.stl"/>
		<mesh name="T-PP" file="assets/fusion_export_2024-11-21_14-46-37/T-PP.stl"/>
		<mesh name="T-AP" file="assets/fusion_export_2024-11-21_14-46-37/T-AP.stl"/>
		<mesh name="I-PP" file="assets/fusion_export_2024-11-21_14-46-37/I-PP.stl"/>
	</asset>
	<worldbody>
		<body name="root" quat="1.0 0.0 0.0 0.0">
			<body name="Tower_MK3_cdd9b821" pos="0.0 0.0 0.0" quat="1.0 0.0 0.0 0.0">
				<body name="Carpals_b89de987" pos="0.194 3.842945022527967e-18 0.0019999999999999463" quat="0.7071067811865475 3.802567673374766e-16 0.7071067811865477 3.802567673374766e-16">
					<body name="M-AP_2d435c57" pos="-0.02452743204997389 0.001568410507072356 0.04973945668647814" quat="0.5175321243695739 0.5647872069009546 0.4342610146809031 -0.4739127370042382">
						<body name="I-PP_067a6ee7" pos="3.7798844171048583e-17 -1.0460497017675653e-16 1.2634448714608842e-17" quat="0.7071067811865475 -1.1102230246251565e-16 -0.7071067811865437 -1.1102230246251565e-16">
							<body name="M-MP_62e98fcf" pos="-2.0578157233774874e-16 1.1470858984896637e-16 0.03999999999999998" quat="1.0000000000000002 4.0939474033052647e-16 1.457167719820518e-16 -3.3306690738754696e-16">
								<body name="M-DP_20fb6377" pos="0.0009999999999998734 -0.00010000000000013676 0.027999999999999782" quat="0.5000000000000023 0.5000000000000018 0.500000000000001 0.5000000000000053">
									<joint name="M-DP_20fb6377_joint" pos="9.999999999992125e-05 -5.378659215064807e-18 -1.170176016631816e-18" axis="-0.9999999999999916 3.6012859361278515e-15 -1.0720591081536668e-15" range="0.0 1.3089969389957472"/>
									<geom mesh="M-DP"/>
								</body>
								<joint name="M-MP_62e98fcf_joint" pos="3.597547411660925e-18 -6.102387480083956e-17 5.305012189775878e-17" axis="2.7755575615628914e-16 -1.0000000000000036 -1.0408340855860843e-16" range="0.0 2.0943951023931953"/>
								<geom mesh="M-MP"/>
							</body>
							<joint name="I-PP_067a6ee7_joint" pos="1.0507725389252553e-18 1.0381299611154882e-17 -1.8073894221564938e-18" axis="8.326672684688674e-16 -1.0000000000000082 -9.506284648352903e-16" range="-0.17453292519943295 2.007128639793479"/>
							<geom mesh="I-PP"/>
						</body>
						<joint name="M-AP_2d435c57_joint" pos="0.0144 -7.068998164605489e-17 9.540979117872439e-18" axis="1.942890293094024e-15 -1.1102230246251565e-16 0.9999999999999977" range="-0.4363323129985824 0.6108652381980153"/>
						<geom mesh="M-AP"/>
					</body>
					<body name="M-AP_38795edc" pos="0.049791901334176054 0.007436435784528562 0.0271529568177391" quat="0.39177943510550195 0.2220571731977528 0.6734235504166661 -0.5862595055127453">
						<body name="P-PP_660f8be8" pos="3.3597277798206454e-17 -9.164200268145919e-18 -3.123216747303648e-18" quat="0.7071067811865476 -5.551115123125783e-17 -0.7071067811865475 0.0">
							<body name="M-MP_b3c5f48d" pos="-6.938893903907228e-18 -2.6454533008646308e-17 0.030000000000000075" quat="0.9999999999999969 1.249000902703301e-16 2.914335439641036e-15 0.0">
								<body name="M-DP_192c8ebb" pos="0.0009999999999998578 -9.999999999997728e-05 0.027999999999999976" quat="0.5000000000000029 0.5000000000000002 0.5 0.5000000000000033">
									<joint name="M-DP_192c8ebb_joint" pos="0.00010000000000000671 4.875352237806302e-17 1.2314164987183018e-17" axis="-0.9999999999999996 2.7755575615628914e-16 -4.718447854656915e-16" range="0.0 1.3089969389957472"/>
									<geom mesh="M-DP"/>
								</body>
								<joint name="M-MP_b3c5f48d_joint" pos="8.591738264962151e-18 2.3773804282340214e-17 -3.419878436337367e-17" axis="-4.996003610813204e-16 -1.0000000000000064 -1.249000902703301e-16" range="0.0 2.0943951023931953"/>
								<geom mesh="M-MP"/>
							</body>
							<joint name="P-PP_660f8be8_joint" pos="-3.237906566374557e-18 -2.1668957835962876e-18 1.5894815400683688e-17" axis="-3.885780586188048e-16 -0.9999999999999996 -8.465450562766819e-16" range="-0.17453292519943295 2.007128639793479"/>
							<geom mesh="P-PP"/>
						</body>
						<joint name="M-AP_38795edc_joint" pos="0.014400000000000007 -1.1275702593849246e-17 1.5829351718288365e-17" axis="-2.7755575615628914e-17 -1.6653345369377348e-16 -1.0000000000000009" range="-0.6108652381980153 0.4363323129985824"/>
						<geom mesh="M-AP"/>
					</body>
					<body name="M-AP_3dd9c1b4" pos="0.023407676073564206 0.0017074271750134034 0.04449569624843634" quat="0.4545194776720436 0.4055797876726393 0.5792279653395693 -0.5416752204197026">
						<body name="M-PP_16d48559" pos="-1.155175252991375e-16 -1.0507927263209634e-16 2.225035862388558e-17" quat="0.707106781186546 2.3869795029440866e-15 -0.7071067811865464 3.3306690738754696e-16">
							<body name="M-MP_6b29c0a1" pos="4.0332320816460765e-17 2.0079424234431542e-16 0.048000000000000154" quat="0.9999999999999978 5.134781488891349e-16 4.2049697057677804e-15 1.3322676295501878e-15">
								<body name="M-DP_3cbbc9d5" pos="0.0009999999999997825 -3.155028321932818e-16 0.02799999999999993" quat="0.5000000000000042 0.4999999999999988 0.4999999999999997 0.5000000000000001">
									<joint name="M-DP_3cbbc9d5_joint" pos="1.2738647990931297e-16 1.203371633436387e-16 -1.0888894666999057e-17" axis="-1.0000000000000004 -2.213507155346406e-15 3.656797087359109e-15" range="0.0 1.3089969389957472"/>
									<geom mesh="M-DP"/>
								</body>
								<joint name="M-MP_6b29c0a1_joint" pos="-6.5678052108806596e-18 7.769990288843462e-17 3.518696938514808e-17" axis="-1.9984014443252818e-15 -0.9999999999999992 2.5396351688300456e-15" range="0.0 2.0943951023931953"/>
								<geom mesh="M-MP"/>
							</body>
							<joint name="M-PP_16d48559_joint" pos="2.1621119931780223e-19 -6.062911924869317e-18 -4.472658181669709e-17" axis="1.887379141862766e-15 -1.0000000000000049 4.1494585545365226e-15" range="-0.17453292519943295 2.007128639793479"/>
							<geom mesh="M-PP"/>
						</body>
						<joint name="M-AP_3dd9c1b4_joint" pos="0.014399999999999923 -5.2475385148298415e-17 -3.903127820947816e-18" axis="-8.326672684688674e-17 2.220446049250313e-16 0.9999999999999979" range="-0.4363323129985824 0.6108652381980153"/>
						<geom mesh="M-AP"/>
					</body>
					<body name="T-AP_871e3420" pos="-0.029597736635895485 0.017975734031793606 -0.019167524381492156" quat="0.7678583570172353 0.4625742495298359 0.05141641370724385 -0.44019877286538484">
						<body name="T-AP_OUT_8c71ff5d" pos="-0.023000000000000527 -7.892991815694472e-17 1.9038590148845458e-16" quat="0.7071067811865489 -0.7071067811865512 4.135580766728708e-15 -6.494804694057166e-15">
							<body name="T-PP_4196528c" pos="1.1963036836192852e-15 1.7439834604616158e-16 6.527685939595936e-16" quat="7.993605777301127e-15 -0.707106781186541 -1.354472090042691e-14 0.7071067811865495">
								<body name="T-DP_448a4de4" pos="3.288385189148535e-16 4.562322741819003e-16 0.029999999999999798" quat="0.499999999999985 0.4999999999999981 0.5000000000000111 0.5000000000000056">
									<joint name="T-DP_448a4de4_joint" pos="-1.2741892527574519e-17 1.005995402266765e-16 9.397995200594752e-17" axis="0.9999999999999917 6.494804694057166e-15 1.62231339473351e-14" range="-1.7453292519943295 0.0"/>
									<geom mesh="T-DP"/>
								</body>
								<joint name="T-PP_4196528c_joint" pos="8.28264772479016e-18 -5.058868245246064e-18 9.571993728557986e-17" axis="1.9984014443252818e-14 -0.9999999999999943 -1.1435297153639112e-14" range="-0.17453292519943295 1.5707963267948966"/>
								<geom mesh="T-PP"/>
							</body>
							<joint name="T-AP_OUT_8c71ff5d_joint" pos="0.023000000000001106 1.6393136847980827e-16 5.915407053080912e-16" axis="-1.5015766408055242e-14 -5.745404152435185e-15 0.999999999999998" range="-0.7853981633974483 0.7853981633974483"/>
							<geom mesh="T-AP_OUT"/>
						</body>
						<joint name="T-AP_871e3420_joint" pos="0.016900000000000383 1.2663481374630692e-16 1.857238321467669e-16" axis="3.0531133177191805e-16 4.440892098500626e-15 0.9999999999999966" range="-1.3089969389957472 1.3089969389957472"/>
						<geom mesh="T-AP"/>
					</body>
					<body name="M-AP_f6857dfb" pos="-0.0009621394664390758 3.257250713100834e-18 0.05335854381555534" quat="0.4999999999999999 0.5000000000000007 0.5000000000000009 -0.5">
						<body name="M-PP_164eb1b0" pos="-2.7755575615628883e-17 7.9797279894933e-17 1.2374273422639382e-17" quat="0.7071067811865471 -4.996003610813204e-16 -0.7071067811865477 -8.881784197001252e-16">
							<body name="M-MP_3c00587d" pos="6.700837908871e-17 2.0030618711694112e-17 0.04800000000000034" quat="0.9999999999999969 -5.0037120657172456e-17 3.925231146709437e-15 -1.6653345369377348e-16">
								<body name="M-DP_05164f11" pos="0.0009999999999998031 1.1275702593849246e-17 0.027999999999999824" quat="0.5000000000000032 0.4999999999999999 0.4999999999999998 0.5000000000000042">
									<joint name="M-DP_05164f11_joint" pos="-1.4745149545802805e-17 -1.4791141972893971e-31 -1.3769367590565884e-16" axis="-0.9999999999999996 6.386501543029423e-16 -1.1761641417377724e-15" range="0.0 1.3089969389957472"/>
									<geom mesh="M-DP"/>
								</body>
								<joint name="M-MP_3c00587d_joint" pos="-8.359114758843884e-17 -9.540979117872525e-18 -1.3877787807815292e-17" axis="-3.3306690738754696e-16 -1.0000000000000029 -3.9403654086199957e-16" range="0.0 2.0943951023931953"/>
								<geom mesh="M-MP"/>
							</body>
							<joint name="M-PP_164eb1b0_joint" pos="-4.789446380758887e-20 -2.407412430484045e-35 -4.887917868404888e-35" axis="4.440892098500626e-16 -0.9999999999999989 -1.6139120735855316e-15" range="-0.17453292519943295 2.007128639793479"/>
							<geom mesh="M-PP"/>
						</body>
						<joint name="M-AP_f6857dfb_joint" pos="0.014399999999999937 2.168404344971009e-17 2.3418766925686896e-17" axis="-1.609823385706477e-15 -5.551115123125783e-17 0.9999999999999982" range="-0.4363323129985824 0.6108652381980153"/>
						<geom mesh="M-AP"/>
					</body>
					<joint name="Carpals_b89de987_joint" pos="0.0020000000000000035 2.71190195469167e-33 -0.05000000000000001" axis="0.9999999999999996 -1.0755285551056194e-15 4.9303806576312877e-32" range="-1.3962634015954636 1.3962634015954636"/>
					<geom mesh="Carpals"/>
				</body>
				<geom mesh="Tower_MK3"/>
			</body>
		</body>
	</worldbody>
	<actuator>
		<position name="Carpals_b89de987_joint_actuator" joint="Carpals_b89de987_joint" ctrlrange="-1.3962634015954636 1.3962634015954636"/>
		<position name="M-AP_f6857dfb_joint_actuator" joint="M-AP_f6857dfb_joint" ctrlrange="-0.4363323129985824 0.6108652381980153"/>
		<position name="M-PP_164eb1b0_joint_actuator" joint="M-PP_164eb1b0_joint" ctrlrange="-0.17453292519943295 2.007128639793479"/>
		<position name="M-MP_3c00587d_joint_actuator" joint="M-MP_3c00587d_joint" ctrlrange="0.0 2.0943951023931953"/>
		<position name="T-AP_871e3420_joint_actuator" joint="T-AP_871e3420_joint" ctrlrange="-1.3089969389957472 1.3089969389957472"/>
		<position name="T-AP_OUT_8c71ff5d_joint_actuator" joint="T-AP_OUT_8c71ff5d_joint" ctrlrange="-0.7853981633974483 0.7853981633974483"/>
		<position name="T-PP_4196528c_joint_actuator" joint="T-PP_4196528c_joint" ctrlrange="-0.17453292519943295 1.5707963267948966"/>
		<position name="T-DP_448a4de4_joint_actuator" joint="T-DP_448a4de4_joint" ctrlrange="-1.7453292519943295 0.0"/>
		<position name="M-AP_3dd9c1b4_joint_actuator" joint="M-AP_3dd9c1b4_joint" ctrlrange="-0.4363323129985824 0.6108652381980153"/>
		<position name="M-PP_16d48559_joint_actuator" joint="M-PP_16d48559_joint" ctrlrange="-0.17453292519943295 2.007128639793479"/>
		<position name="M-MP_6b29c0a1_joint_actuator" joint="M-MP_6b29c0a1_joint" ctrlrange="0.0 2.0943951023931953"/>
		<position name="M-AP_38795edc_joint_actuator" joint="M-AP_38795edc_joint" ctrlrange="-0.6108652381980153 0.4363323129985824"/>
		<position name="P-PP_660f8be8_joint_actuator" joint="P-PP_660f8be8_joint" ctrlrange="-0.17453292519943295 2.007128639793479"/>
		<position name="M-MP_b3c5f48d_joint_actuator" joint="M-MP_b3c5f48d_joint" ctrlrange="0.0 2.0943951023931953"/>
		<position name="M-AP_2d435c57_joint_actuator" joint="M-AP_2d435c57_joint" ctrlrange="-0.4363323129985824 0.6108652381980153"/>
		<position name="I-PP_067a6ee7_joint_actuator" joint="I-PP_067a6ee7_joint" ctrlrange="-0.17453292519943295 2.007128639793479"/>
		<position name="M-MP_62e98fcf_joint_actuator" joint="M-MP_62e98fcf_joint" ctrlrange="0.0 2.0943951023931953"/>
	</actuator>
	<contact>
		<exclude body1="root" body2="Tower_MK3_cdd9b821"/>
		<exclude body1="Tower_MK3_cdd9b821" body2="Carpals_b89de987"/>
		<exclude body1="Carpals_b89de987" body2="M-AP_f6857dfb"/>
		<exclude body1="M-AP_f6857dfb" body2="M-PP_164eb1b0"/>
		<exclude body1="M-PP_164eb1b0" body2="M-MP_3c00587d"/>
		<exclude body1="M-MP_3c00587d" body2="M-DP_05164f11"/>
		<exclude body1="Carpals_b89de987" body2="T-AP_871e3420"/>
		<exclude body1="T-AP_871e3420" body2="T-AP_OUT_8c71ff5d"/>
		<exclude body1="T-AP_OUT_8c71ff5d" body2="T-PP_4196528c"/>
		<exclude body1="T-PP_4196528c" body2="T-DP_448a4de4"/>
		<exclude body1="Carpals_b89de987" body2="M-AP_3dd9c1b4"/>
		<exclude body1="M-AP_3dd9c1b4" body2="M-PP_16d48559"/>
		<exclude body1="M-PP_16d48559" body2="M-MP_6b29c0a1"/>
		<exclude body1="M-MP_6b29c0a1" body2="M-DP_3cbbc9d5"/>
		<exclude body1="Carpals_b89de987" body2="M-AP_38795edc"/>
		<exclude body1="M-AP_38795edc" body2="P-PP_660f8be8"/>
		<exclude body1="P-PP_660f8be8" body2="M-MP_b3c5f48d"/>
		<exclude body1="M-MP_b3c5f48d" body2="M-DP_192c8ebb"/>
		<exclude body1="Carpals_b89de987" body2="M-AP_2d435c57"/>
		<exclude body1="M-AP_2d435c57" body2="I-PP_067a6ee7"/>
		<exclude body1="I-PP_067a6ee7" body2="M-MP_62e98fcf"/>
		<exclude body1="M-MP_62e98fcf" body2="M-DP_20fb6377"/>
	</contact>
	<equality>
		<joint joint1="M-DP_05164f11_joint" joint2="M-MP_3c00587d_joint" polycoef="0 0.5833333333333334 0 0 0"/>
			<joint joint1="M-DP_3cbbc9d5_joint" joint2="M-MP_6b29c0a1_joint" polycoef="0 0.5833333333333334 0 0 0"/>
				<joint joint1="M-DP_192c8ebb_joint" joint2="M-MP_b3c5f48d_joint" polycoef="0 0.5833333333333334 0 0 0"/>
					<joint joint1="M-DP_20fb6377_joint" joint2="M-MP_62e98fcf_joint" polycoef="0 0.5833333333333334 0 0 0"/>
	</equality>
</mujoco>