<mujoco model="DexterousDynamos">
	<compiler angle="radian"/>
	<default>
		<geom rgba="1 1 1 1" type="mesh" friction="1 0.005 0.001" condim="3" margin="0.0005" contype="1" conaffinity="1"/>
		<joint type="hinge" limited="true" damping="0.1" armature="0.001" margin="0.01" frictionloss="0.001"/>
		<position ctrllimited="true" forcelimited="true" forcerange="-1 1" kp="2.0"/>
		<mesh scale="0.001 0.001 0.001"/>
	</default>
	<asset>
		<mesh name="M-PP" file="assets/fusion_export_2024-11-23_00-53-00/M-PP.stl"/>
		<mesh name="I-Assembly" file="assets/fusion_export_2024-11-23_00-53-00/I-Assembly.stl"/>
		<mesh name="M-Assembly" file="assets/fusion_export_2024-11-23_00-53-00/M-Assembly.stl"/>
		<mesh name="P-Assembly" file="assets/fusion_export_2024-11-23_00-53-00/P-Assembly.stl"/>
		<mesh name="P-PP" file="assets/fusion_export_2024-11-23_00-53-00/P-PP.stl"/>
		<mesh name="Carpals" file="assets/fusion_export_2024-11-23_00-53-00/Carpals.stl"/>
		<mesh name="M-MP" file="assets/fusion_export_2024-11-23_00-53-00/M-MP.stl"/>
		<mesh name="T-Assembly" file="assets/fusion_export_2024-11-23_00-53-00/T-Assembly.stl"/>
		<mesh name="T-DP" file="assets/fusion_export_2024-11-23_00-53-00/T-DP.stl"/>
		<mesh name="Tower_MK3" file="assets/fusion_export_2024-11-23_00-53-00/Tower_MK3.stl"/>
		<mesh name="M-AP" file="assets/fusion_export_2024-11-23_00-53-00/M-AP.stl"/>
		<mesh name="T-AP_OUT" file="assets/fusion_export_2024-11-23_00-53-00/T-AP_OUT.stl"/>
		<mesh name="M-DP" file="assets/fusion_export_2024-11-23_00-53-00/M-DP.stl"/>
		<mesh name="T-PP" file="assets/fusion_export_2024-11-23_00-53-00/T-PP.stl"/>
		<mesh name="T-AP" file="assets/fusion_export_2024-11-23_00-53-00/T-AP.stl"/>
		<mesh name="I-PP" file="assets/fusion_export_2024-11-23_00-53-00/I-PP.stl"/>
	</asset>
	<worldbody>
		<body name="root" quat="1.0 0.0 0.0 0.0">
			<body name="Tower_MK3_cdd9b821" pos="0.0 0.0 0.0" quat="1.0 0.0 0.0 0.0">
				<body name="Carpals_b89de987" pos="0.193999986406645 -3.686916491009634e-05 0.00199999999999996" quat="0.7071067331267782 0.00026070438296540136 0.7071067331267784 -0.0002607043829654448">
					<body name="M-AP_00c7e80f" pos="-0.0245295299049941 0.0015685968794313 0.04973908661681349" quat="0.5175673106841562 0.5648194489682893 0.43421907836693324 -0.4738743092429697">
						<body name="I-PP_cf0e2182" pos="-6.632322171561797e-17 -1.3589913003259047e-16 1.0118328419349886e-17" quat="0.7064409996809056 -3.3306690738754696e-16 -0.7077719364101978 -2.220446049250313e-16">
							<body name="M-MP_5fd212cd" pos="-1.8431436932253575e-17 4.336808689942018e-18 0.040000000000000036" quat="1.0 -3.469446951953614e-17 7.632783294297951e-17 5.551115123125783e-17">
								<body name="M-DP_f8cbda88" pos="0.0009999999999999844 -0.00010000000000002314 0.028000000000000018" quat="0.5000000000000004 0.49999999999999944 0.4999999999999999 0.4999999999999997">
									<joint name="M-DP_f8cbda88_joint" pos="9.999999999994138e-05 -5.371544138307871e-17 -3.0201383250825706e-17" axis="-0.9999999999999996 -2.0261570199409107e-15 1.0547118733938987e-15" range="0.0 1.3089969389957472"/>
									<geom mesh="M-DP"/>
								</body>
								<joint name="M-MP_5fd212cd_joint" pos="-1.722275552576525e-17 -2.4110002110676104e-17 3.2175644141916336e-17" axis="8.326672684688674e-16 -0.9999999999999992 -9.506284648352903e-16" range="0.0 2.0943951023931953"/>
								<geom mesh="M-MP"/>
							</body>
							<joint name="I-PP_cf0e2182_joint" pos="2.2103198581084714e-18 7.053339437169385e-18 -1.2080891234349761e-18" axis="9.992007221626409e-16 -1.000000000000004 -1.0130785099704553e-15" range="-0.17453292519943295 2.007128639793479"/>
							<geom mesh="I-PP"/>
						</body>
						<joint name="M-AP_00c7e80f_joint" pos="0.014399999999999956 -1.0278236595162582e-16 1.431146867680866e-17" axis="-5.551115123125783e-17 1.2212453270876722e-15 0.9999999999999968" range="-0.4363323129985824 0.6108652381980153"/>
						<geom mesh="M-AP"/>
					</body>
					<body name="M-AP_48910c27" pos="0.04979641298344026 0.007437708668019195 0.02714929329024474" quat="0.39165831717623767 0.22191805252953492 0.6734694086488737 -0.5863404268531313">
						<body name="P-PP_13f0f3d3" pos="2.028230347434807e-17 7.612199969945414e-18 2.3533653782354537e-17" quat="0.7065579686474562 2.220446049250313e-16 -0.7076551681015123 -1.6653345369377348e-16">
							<body name="M-MP_2bfd2f04" pos="-1.9081958235744878e-17 -4.119968255444917e-17 0.030000000000000054" quat="1.0 -2.7755575615628914e-17 -2.7755575615628914e-17 0.0">
								<body name="M-DP_5f0d2926" pos="0.0009999999999999814 -0.0001000000000000085 0.027999999999999994" quat="0.5000000000000003 0.49999999999999983 0.5000000000000001 0.5000000000000002">
									<joint name="M-DP_5f0d2926_joint" pos="0.00010000000000001497 7.207742161365743e-17 2.9290399316053706e-18" axis="-1.0000000000000002 -3.0531133177191805e-16 -7.355227538141662e-16" range="0.0 1.3089969389957472"/>
									<geom mesh="M-DP"/>
								</body>
								<joint name="M-MP_2bfd2f04_joint" pos="-1.171869695207721e-18 8.725104538385514e-18 2.4424879789821522e-17" axis="-4.440892098500626e-16 -1.0000000000000004 -8.326672684688674e-17" range="0.0 2.0943951023931953"/>
								<geom mesh="M-MP"/>
							</body>
							<joint name="P-PP_13f0f3d3_joint" pos="3.833184058085544e-18 -7.922763782835389e-18 -1.4973823299787632e-17" axis="-3.885780586188048e-16 -1.0000000000000004 -2.636779683484747e-16" range="-0.17453292519943295 2.007128639793479"/>
							<geom mesh="P-PP"/>
						</body>
						<joint name="M-AP_48910c27_joint" pos="0.014400000000000012 -2.211772431870429e-17 1.5178830414797062e-17" axis="-1.942890293094024e-16 6.661338147750939e-16 -1.0000000000000004" range="-0.6108652381980153 0.4363323129985824"/>
						<geom mesh="M-AP"/>
					</body>
					<body name="M-AP_c9980cc4" pos="0.023409547989986016 0.001707590946479374 0.04449519261795145" quat="0.4544828874453351 0.4055406609370029 0.5792553602054793 -0.5417059211595832">
						<body name="M-PP_32fb69bf" pos="-9.671662353485037e-17 -1.436600671481805e-17 -8.2368532432625e-18" quat="0.7065050981872625 3.885780586188048e-16 -0.7077079526438891 3.3306690738754696e-16">
							<body name="M-MP_93965ca4" pos="-2.5587171270657905e-17 -9.107298248878237e-18 0.04800000000000008" quat="1.0 0.0 -2.0816681711721685e-16 5.551115123125783e-17">
								<body name="M-DP_caab02f8" pos="0.0009999999999999979 9.107298248878237e-18 0.02799999999999996" quat="0.5000000000000006 0.49999999999999917 0.5000000000000002 0.49999999999999906">
									<joint name="M-DP_caab02f8_joint" pos="1.3721384550404466e-16 6.547177265705249e-17 4.2773936368871135e-17" axis="-1.0000000000000004 -8.881784197001252e-16 9.020562075079397e-17" range="0.0 1.3089969389957472"/>
									<geom mesh="M-DP"/>
								</body>
								<joint name="M-MP_93965ca4_joint" pos="2.4785122580526127e-17 9.905120299520399e-17 1.2157278934836427e-17" axis="-2.7755575615628914e-16 -0.9999999999999994 1.734723475976807e-15" range="0.0 2.0943951023931953"/>
								<geom mesh="M-MP"/>
							</body>
							<joint name="M-PP_32fb69bf_joint" pos="-2.763004548120401e-19 -6.477168015932836e-18 -1.61034059853451e-17" axis="-5.551115123125783e-17 -1.0000000000000022 1.7139067942650854e-15" range="-0.17453292519943295 2.007128639793479"/>
							<geom mesh="M-PP"/>
						</body>
						<joint name="M-AP_c9980cc4_joint" pos="0.014399999999999944 -5.941427905220564e-17 -1.5178830414797062e-17" axis="6.38378239159465e-16 7.771561172376096e-16 0.9999999999999978" range="-0.4363323129985824 0.6108652381980153"/>
						<geom mesh="M-AP"/>
					</body>
					<body name="T-AP_ac170ba5" pos="-0.029597736635895423 0.017975734031793388 -0.019167524381491743" quat="-0.46257424952983467 0.7678583570172343 -0.4401987728653877 -0.05141641370724577">
						<body name="T-AP_OUT_a7c38301" pos="-0.0230000000000005 5.715913853343579e-16 1.0722759485881639e-16" quat="0.5372996083468241 0.8433914458128913 -1.3322676295501878e-15 6.938893903907228e-16">
							<body name="T-PP_1254f8d5" pos="1.2074684138542838e-15 1.7919654376385695e-16 6.544144197250373e-16" quat="-2.9976021664879227e-15 -0.7071067811865377 1.1102230246251565e-15 0.7071067811865492">
								<body name="T-DP_aed3379a" pos="9.519295074422729e-17 4.77048955893622e-16 0.030000000000000023" quat="0.4999999999999998 0.5000000000000075 0.5000000000000006 0.5000000000000013">
									<joint name="T-DP_aed3379a_joint" pos="6.3846885802101e-17 2.638575629691531e-17 2.8715865630147274e-17" axis="0.9999999999999958 -9.992007221626409e-16 1.7486012637846216e-15" range="-1.7453292519943295 0.0"/>
									<geom mesh="T-DP"/>
								</body>
								<joint name="T-PP_1254f8d5_joint" pos="6.8988979146713415e-18 2.155793885708645e-17 2.0127088287987651e-16" axis="-6.8833827526759706e-15 -0.9999999999999959 -7.993605777301127e-15" range="-0.17453292519943295 1.5707963267948966"/>
								<geom mesh="T-PP"/>
							</body>
							<joint name="T-AP_OUT_a7c38301_joint" pos="0.023000000000001172 9.367506770274758e-17 3.499533562240087e-16" axis="1.0824674490095276e-15 -0.42261826174070033 -0.9063077870366472" range="-0.7853981633974483 0.7853981633974483"/>
							<geom mesh="T-AP_OUT"/>
						</body>
						<joint name="T-AP_ac170ba5_joint" pos="0.016900000000000366 6.505213034913027e-17 1.8106176280507924e-16" axis="1.1657341758564144e-15 -2.220446049250313e-15 -0.9999999999999962" range="-1.3089969389957472 1.3089969389957472"/>
						<geom mesh="T-AP"/>
					</body>
					<body name="M-AP_bb9fccd7" pos="-0.0009621394664390685 2.375080384101058e-18 0.053358543815555326" quat="0.5000000000000004 0.49999999999999983 0.5 -0.5000000000000008">
						<body name="M-PP_5eafbf69" pos="-4.1633372091515825e-17 2.7755575615628864e-17 -3.594699893231231e-21" quat="0.706460881922205 -2.220446049250313e-16 -0.7077520909991706 -2.220446049250313e-16">
							<body name="M-MP_7fda9f69" pos="-8.63312920500528e-17 -9.330914946953373e-18 0.048000000000000154" quat="1.0 3.0574501264091225e-17 0.0 0.0">
								<body name="M-DP_94d2158a" pos="0.0009999999999999404 -6.451002926288751e-18 0.028000000000000025" quat="0.5000000000000008 0.5 0.4999999999999998 0.5000000000000008">
									<joint name="M-DP_94d2158a_joint" pos="1.5612511283791412e-17 -1.3361333028928368e-19 1.2273161319545561e-16" axis="-0.9999999999999994 1.159735553967606e-16 6.744138602805412e-17" range="0.0 1.3089969389957472"/>
									<geom mesh="M-DP"/>
								</body>
								<joint name="M-MP_7fda9f69_joint" pos="6.817933558779142e-17 6.938893903907302e-18 -7.4224300060933e-20" axis="-1.6653345369377348e-16 -1.0000000000000004 9.75781955236954e-18" range="0.0 2.0943951023931953"/>
								<geom mesh="M-MP"/>
							</body>
							<joint name="M-PP_5eafbf69_joint" pos="-1.5108221092759517e-20 9.7018720948507e-33 -1.3877779583938463e-17" axis="-1.1102230246251565e-16 -1.0000000000000009 9.75781955236954e-18" range="-0.17453292519943295 2.007128639793479"/>
							<geom mesh="M-PP"/>
						</body>
						<joint name="M-AP_bb9fccd7_joint" pos="0.014400000000000015 2.0816681711721685e-17 -2.0383000842727483e-17" axis="1.3877787807814457e-15 1.1102230246251565e-16 0.9999999999999987" range="-0.4363323129985824 0.6108652381980153"/>
						<geom mesh="M-AP"/>
					</body>
					<joint name="Carpals_b89de987_joint" pos="0.0019999999999999996 1.0164395367051604e-20 -0.04999999999999999" axis="0.9999999999999993 6.127748595140475e-17 6.118716649654125e-17" range="-1.3962634015954636 1.3962634015954636"/>
					<geom mesh="Carpals"/>
				</body>
				<geom mesh="Tower_MK3"/>
			</body>
		</body>
	</worldbody>
	<actuator>
		<position name="Carpals_b89de987_joint_actuator" joint="Carpals_b89de987_joint" ctrlrange="-1.3962634015954636 1.3962634015954636"/>
		<position name="M-AP_bb9fccd7_joint_actuator" joint="M-AP_bb9fccd7_joint" ctrlrange="-0.4363323129985824 0.6108652381980153"/>
		<position name="M-PP_5eafbf69_joint_actuator" joint="M-PP_5eafbf69_joint" ctrlrange="-0.17453292519943295 2.007128639793479"/>
		<position name="M-MP_7fda9f69_joint_actuator" joint="M-MP_7fda9f69_joint" ctrlrange="0.0 2.0943951023931953"/>
		<position name="T-AP_ac170ba5_joint_actuator" joint="T-AP_ac170ba5_joint" ctrlrange="-1.3089969389957472 1.3089969389957472"/>
		<position name="T-AP_OUT_a7c38301_joint_actuator" joint="T-AP_OUT_a7c38301_joint" ctrlrange="-0.7853981633974483 0.7853981633974483"/>
		<position name="T-PP_1254f8d5_joint_actuator" joint="T-PP_1254f8d5_joint" ctrlrange="-0.17453292519943295 1.5707963267948966"/>
		<position name="M-AP_c9980cc4_joint_actuator" joint="M-AP_c9980cc4_joint" ctrlrange="-0.4363323129985824 0.6108652381980153"/>
		<position name="M-PP_32fb69bf_joint_actuator" joint="M-PP_32fb69bf_joint" ctrlrange="-0.17453292519943295 2.007128639793479"/>
		<position name="M-MP_93965ca4_joint_actuator" joint="M-MP_93965ca4_joint" ctrlrange="0.0 2.0943951023931953"/>
		<position name="M-AP_48910c27_joint_actuator" joint="M-AP_48910c27_joint" ctrlrange="-0.6108652381980153 0.4363323129985824"/>
		<position name="P-PP_13f0f3d3_joint_actuator" joint="P-PP_13f0f3d3_joint" ctrlrange="-0.17453292519943295 2.007128639793479"/>
		<position name="M-MP_2bfd2f04_joint_actuator" joint="M-MP_2bfd2f04_joint" ctrlrange="0.0 2.0943951023931953"/>
		<position name="M-AP_00c7e80f_joint_actuator" joint="M-AP_00c7e80f_joint" ctrlrange="-0.4363323129985824 0.6108652381980153"/>
		<position name="I-PP_cf0e2182_joint_actuator" joint="I-PP_cf0e2182_joint" ctrlrange="-0.17453292519943295 2.007128639793479"/>
		<position name="M-MP_5fd212cd_joint_actuator" joint="M-MP_5fd212cd_joint" ctrlrange="0.0 2.0943951023931953"/>
	</actuator>
	<contact>
		<exclude body1="root" body2="Tower_MK3_cdd9b821"/>
		<exclude body1="Tower_MK3_cdd9b821" body2="Carpals_b89de987"/>
		<exclude body1="Carpals_b89de987" body2="M-AP_bb9fccd7"/>
		<exclude body1="M-AP_bb9fccd7" body2="M-PP_5eafbf69"/>
		<exclude body1="M-PP_5eafbf69" body2="M-MP_7fda9f69"/>
		<exclude body1="M-MP_7fda9f69" body2="M-DP_94d2158a"/>
		<exclude body1="Carpals_b89de987" body2="T-AP_ac170ba5"/>
		<exclude body1="T-AP_ac170ba5" body2="T-AP_OUT_a7c38301"/>
		<exclude body1="T-AP_OUT_a7c38301" body2="T-PP_1254f8d5"/>
		<exclude body1="T-PP_1254f8d5" body2="T-DP_aed3379a"/>
		<exclude body1="Carpals_b89de987" body2="M-AP_c9980cc4"/>
		<exclude body1="M-AP_c9980cc4" body2="M-PP_32fb69bf"/>
		<exclude body1="M-PP_32fb69bf" body2="M-MP_93965ca4"/>
		<exclude body1="M-MP_93965ca4" body2="M-DP_caab02f8"/>
		<exclude body1="Carpals_b89de987" body2="M-AP_48910c27"/>
		<exclude body1="M-AP_48910c27" body2="P-PP_13f0f3d3"/>
		<exclude body1="P-PP_13f0f3d3" body2="M-MP_2bfd2f04"/>
		<exclude body1="M-MP_2bfd2f04" body2="M-DP_5f0d2926"/>
		<exclude body1="Carpals_b89de987" body2="M-AP_00c7e80f"/>
		<exclude body1="M-AP_00c7e80f" body2="I-PP_cf0e2182"/>
		<exclude body1="I-PP_cf0e2182" body2="M-MP_5fd212cd"/>
		<exclude body1="M-MP_5fd212cd" body2="M-DP_f8cbda88"/>
	</contact>
	<equality>
		<joint joint1="M-DP_94d2158a_joint" joint2="M-MP_7fda9f69_joint" polycoef="0 0.5833333333333334 0 0 0"/>
			<joint joint1="T-DP_aed3379a_joint" joint2="T-PP_1254f8d5_joint" polycoef="0 0.5833333333333334 0 0 0"/>
				<joint joint1="M-DP_caab02f8_joint" joint2="M-MP_93965ca4_joint" polycoef="0 0.5833333333333334 0 0 0"/>
					<joint joint1="M-DP_5f0d2926_joint" joint2="M-MP_2bfd2f04_joint" polycoef="0 0.5833333333333334 0 0 0"/>
						<joint joint1="M-DP_f8cbda88_joint" joint2="M-MP_5fd212cd_joint" polycoef="0 0.5833333333333334 0 0 0"/>
	</equality>
</mujoco>