<mujoco model="DexterousDynamos">
	<compiler angle="radian"/>
	<option integrator="RK4" timestep="0.0001"/>
	<default>
		<default class="collision">
			<geom contype="1" conaffinity="1" group="4"/>
		</default>
		<default class="visual">
			<geom contype="0" conaffinity="0" group="1" mass="0"/>
		</default>
		<geom type="mesh" quat="1 0 0 0"/>
		<position ctrllimited="true" kp="1"/>
		<velocity ctrllimited="true" kv="0.1"/>
		<motor ctrllimited="true"/>
		<mesh scale="0.001 0.001 0.001"/>
		<joint type="hinge" limited="true"/>
	</default>
	<asset>
		<mesh name="T-PP" file="/home/arturo/Documents/DexterousDynamos/old/mujoco/assets/fusion_export_2024-11-14_21-01-59/T-PP.stl"/>
		<mesh name="M-DP" file="/home/arturo/Documents/DexterousDynamos/old/mujoco/assets/fusion_export_2024-11-14_21-01-59/M-DP.stl"/>
		<mesh name="I-PP" file="/home/arturo/Documents/DexterousDynamos/old/mujoco/assets/fusion_export_2024-11-14_21-01-59/I-PP.stl"/>
		<mesh name="T-AP_OUT" file="/home/arturo/Documents/DexterousDynamos/old/mujoco/assets/fusion_export_2024-11-14_21-01-59/T-AP_OUT.stl"/>
		<mesh name="M-MP" file="/home/arturo/Documents/DexterousDynamos/old/mujoco/assets/fusion_export_2024-11-14_21-01-59/M-MP.stl"/>
		<mesh name="T-DP" file="/home/arturo/Documents/DexterousDynamos/old/mujoco/assets/fusion_export_2024-11-14_21-01-59/T-DP.stl"/>
		<mesh name="Carpals" file="/home/arturo/Documents/DexterousDynamos/old/mujoco/assets/fusion_export_2024-11-14_21-01-59/Carpals.stl"/>
		<mesh name="P-PP" file="/home/arturo/Documents/DexterousDynamos/old/mujoco/assets/fusion_export_2024-11-14_21-01-59/P-PP.stl"/>
		<mesh name="M-PP" file="/home/arturo/Documents/DexterousDynamos/old/mujoco/assets/fusion_export_2024-11-14_21-01-59/M-PP.stl"/>
		<mesh name="T-Assembly" file="/home/arturo/Documents/DexterousDynamos/old/mujoco/assets/fusion_export_2024-11-14_21-01-59/T-Assembly.stl"/>
		<mesh name="M-Assembly" file="/home/arturo/Documents/DexterousDynamos/old/mujoco/assets/fusion_export_2024-11-14_21-01-59/M-Assembly.stl"/>
		<mesh name="M-AP" file="/home/arturo/Documents/DexterousDynamos/old/mujoco/assets/fusion_export_2024-11-14_21-01-59/M-AP.stl"/>
		<mesh name="P-Assembly" file="/home/arturo/Documents/DexterousDynamos/old/mujoco/assets/fusion_export_2024-11-14_21-01-59/P-Assembly.stl"/>
		<mesh name="I-Assembly" file="/home/arturo/Documents/DexterousDynamos/old/mujoco/assets/fusion_export_2024-11-14_21-01-59/I-Assembly.stl"/>
		<mesh name="T-AP" file="/home/arturo/Documents/DexterousDynamos/old/mujoco/assets/fusion_export_2024-11-14_21-01-59/T-AP.stl"/>
	</asset>
	<worldbody>
		<body name="Carpals:1/1" pos="-0.00238190957064469 7.700894238483372e-05 0.04535823796707634" quat="0.9961946980917453 5.496135425675145e-18 0.08715574274765797 -1.7282897140538871e-16">
			<geom class="visual" mesh="Carpals"/>
			<geom class="collision" mesh="Carpals"/>
		</body>
		<body name="M-AP:1/8" pos="0.011695148844910646 7.700894238483532e-05 0.09568777716547133" quat="-0.3265055756219768 -0.3265055756219776 -0.62721137512625 0.6272113751262504">
			<joint name="Middle:AP" type="hinge" pos="0.015 0 0" axis="0 0 1" range="0 0.95"/>
			<body name="M-PP:1/4" pos="1.8843021096399572e-16 9.382154005942786e-17 -2.640032290002196e-17" quat="0.7660444431189772 -4.440892098500626e-16 -0.6427876096865388 -6.106226635438361e-16">
				<joint name="Middle:PP" type="hinge" pos="0 0 0" axis="0 -1 0" range="0 1.5"/>
				<body name="M-MP:1/3" pos="-4.5102810375396984e-17 -8.673617379884035e-19 0.04800000000000042" quat="0.9999999999999979 5.551115123125783e-17 2.706168622523819e-15 1.1102230246251565e-16">
					<joint name="Middle:MP" type="hinge" pos="0 0 0" axis="0 -1 0" range="0 1.95"/>
					<body name="M-DP:1/2" pos="0.0009999999999998526 -0.00010000000000001284 0.02799999999999979" quat="0.5000000000000026 0.5000000000000002 0.49999999999999967 0.5000000000000034">
						<joint name="Middle:DP" type="hinge" pos="0 0 0" axis="-1 0 0" range="0 1.65"/>
						<geom class="visual" mesh="M-DP"/>
						<geom class="collision" mesh="M-DP"/>
					</body>
					<geom class="visual" mesh="M-MP"/>
					<geom class="collision" mesh="M-MP"/>
				</body>
				<geom class="visual" mesh="M-PP"/>
				<geom class="collision" mesh="M-PP"/>
			</body>
			<geom class="visual" mesh="M-AP"/>
			<geom class="collision" mesh="M-AP"/>
		</body>
		<body name="M-AP:1/9" pos="0.033278448631548725 0.002764430408752333 0.08132977454939135" quat="0.2683258905068151 0.21490326953787697 0.6792523851210241 -0.6484088205237933">
			<joint name="Ring:AP" type="hinge" pos="0.015 0 0" axis="0 0 1" range="0 0.95"/>
			<body name="M-PP:1/10" pos="-1.1690705480312684e-16 4.3671336227542125e-17 8.630645624194291e-18" quat="0.7660444431189766 3.3306690738754696e-16 -0.6427876096865381 1.1102230246251565e-16">
				<joint name="Ring:PP" type="hinge" pos="0 0 0" axis="0 -1 0" range="0 1.5"/>
				<body name="M-MP:1/7" pos="1.5612511283791264e-17 -2.0816681711721685e-17 0.048000000000000015" quat="0.9999999999999978 8.326672684688674e-17 3.0808688933348094e-15 -1.6653345369377348e-16">
					<joint name="Ring:MP" type="hinge" pos="0 0 0" axis="0 -1 0" range="0 1.9"/>
					<body name="M-DP:1/6" pos="0.0009999999999998656 -0.00010000000000006011 0.028000000000000084" quat="0.5000000000000037 0.4999999999999992 0.5 0.5000000000000006">
						<joint name="Ring:DP" type="hinge" pos="0 0 0" axis="-1 0 0" range="0 1.65"/>
						<geom class="visual" mesh="M-DP"/>
						<geom class="collision" mesh="M-DP"/>
					</body>
					<geom class="visual" mesh="M-MP"/>
					<geom class="collision" mesh="M-MP"/>
				</body>
				<geom class="visual" mesh="M-PP"/>
				<geom class="collision" mesh="M-PP"/>
			</body>
			<geom class="visual" mesh="M-AP"/>
			<geom class="collision" mesh="M-AP"/>
		</body>
		<body name="M-AP:1/14" pos="-0.011793425899869677 0.0016131128360923437 0.09725201655419126" quat="-0.3535533905932742 -0.4055797876726407 -0.5792279653395715 0.6123724356957955">
			<joint name="Index:AP" type="hinge" pos="0.015 0 0" axis="0 0 1" range="0 0.95"/>
			<body name="I-PP:1/15" pos="5.150136399827679e-16 -5.3645723691710045e-17 1.7467264640023975e-18" quat="0.7660444431189807 -5.551115123125783e-16 -0.6427876096865364 -3.3306690738754696e-16">
				<joint name="Index:PP" type="hinge" pos="0 0 0" axis="0 -1 0" range="0 1.515"/>
				<body name="M-MP:1/13" pos="-3.382710778154774e-16 3.9898639947466563e-17 0.03999999999999958" quat="0.9999999999999999 4.0245584642661925e-16 -7.424616477180734e-16 -2.220446049250313e-16">
					<joint name="Index:MP" type="hinge" pos="0 0 0" axis="0 -1 0" range="0 2"/>
					<body name="M-DP:1/12" pos="0.0009999999999998127 -0.00010000000000014511 0.027999999999999386" quat="0.5000000000000014 0.4999999999999982 0.49999999999999734 0.5000000000000033">
						<joint name="Index:DP" type="hinge" pos="0 0 0" axis="-1 0 0" range="0 1.6"/>
						<geom class="visual" mesh="M-DP"/>
						<geom class="collision" mesh="M-DP"/>
					</body>
					<geom class="visual" mesh="M-MP"/>
					<geom class="collision" mesh="M-MP"/>
				</body>
				<geom class="visual" mesh="I-PP"/>
				<geom class="collision" mesh="I-PP"/>
			</body>
			<geom class="visual" mesh="M-AP"/>
			<geom class="collision" mesh="M-AP"/>
		</body>
		<body name="T-AP:1/17" pos="-0.042327065839604355 0.008382084633197874 0.016849370907237843" quat="-0.41493551278935037 0.8978947437811953 0.036940052858549344 0.14229891711165946">
			<joint name="Thumb:AP" type="hinge" pos="0.0175 0 0" axis="0 0 1" range="0 2.25"/>
			<body name="T-AP_OUT:1/18" pos="-0.01626345596729065 1.0512424264419451e-15 0.016263455967290896" quat="0.6532814824381884 0.653281482438197 0.2705980500730959 -0.2705980500730881">
				<joint name="Thumb:PP" type="hinge" pos="0.023 0 0" axis="0 0 1" range="0 1.575"/>
				<body name="T-PP:1/19" pos="1.2710348209084786e-15 1.901726345105347e-16 9.2922765574284e-16" quat="1.1934897514720433e-15 -0.7660444431189752 -3.3861802251067274e-15 0.6427876096865379">
					<joint name="Thumb:MP" type="hinge" pos="0 0 0" axis="0 -1 0" range="0 1.4"/>
					<body name="T-DP:1/20" pos="4.766152750246277e-16 3.7643499428696714e-16 0.030000000000000002" quat="0.4999999999999937 0.5000000000000095 0.4999999999999981 0.4999999999999997">
						<joint name="Thumb:DP" type="hinge" pos="0 0 0" axis="-1 0 0" range="0 1.6"/>
						<geom class="visual" mesh="T-DP"/>
						<geom class="collision" mesh="T-DP"/>
					</body>
					<geom class="visual" mesh="T-PP"/>
					<geom class="collision" mesh="T-PP"/>
				</body>
				<geom class="visual" mesh="T-AP_OUT"/>
				<geom class="collision" mesh="T-AP_OUT"/>
			</body>
			<geom class="visual" mesh="T-AP"/>
			<geom class="collision" mesh="T-AP"/>
		</body>
		<body name="M-AP:1/24" pos="0.049468640722696855 0.009761841595827506 0.0634783811871559" quat="0.25026098332500024 0.07641128912197266 0.7209909801985281 -0.6416406795023909">
			<joint name="Pinky:AP" type="hinge" pos="0.015 0 0" axis="0 0 1" range="0 0.95"/>
			<body name="P-PP:1/25" pos="3.3689711733889896e-16 4.79020458533684e-17 -5.4767624688648634e-17" quat="0.7660444431189763 -4.440892098500626e-16 -0.6427876096865404 0.0">
				<joint name="Pinky:PP" type="hinge" pos="0 0 0" axis="0 -1 0" range="0 1.6"/>
				<body name="M-MP:1/23" pos="9.107298248878237e-17 -5.637851296924623e-17 0.029999999999999975" quat="0.9999999999999973 5.828670879282072e-16 4.274358644806853e-15 -4.440892098500626e-16">
					<joint name="Pinky:MP" type="hinge" pos="0 0 0" axis="0 -1 0" range="0 1.9"/>
					<body name="M-DP:1/22" pos="0.000999999999999948 -0.00010000000000002542 0.02800000000000011" quat="0.500000000000003 0.49999999999999817 0.5000000000000002 0.5000000000000011">
						<joint name="Pinky:DP" type="hinge" pos="0 0 0" axis="-1 0 0" range="0 1.65"/>
						<geom class="visual" mesh="M-DP"/>
						<geom class="collision" mesh="M-DP"/>
					</body>
					<geom class="visual" mesh="M-MP"/>
					<geom class="collision" mesh="M-MP"/>
				</body>
				<geom class="visual" mesh="P-PP"/>
				<geom class="collision" mesh="P-PP"/>
			</body>
			<geom class="visual" mesh="M-AP"/>
			<geom class="collision" mesh="M-AP"/>
		</body>
	</worldbody>
	<actuator>
		<motor name="C:Middle:AP" joint="Middle:AP" ctrlrange="0 0.95"/>
		<motor name="C:Middle:PP" joint="Middle:PP" ctrlrange="0 1.5"/>
		<motor name="C:Middle:MPDP" joint="Middle:MP" ctrlrange="0 1.65"/>

		<motor name="C:Ring:AP" joint="Ring:AP" ctrlrange="0 0.95"/>
		<motor name="C:Ring:PP" joint="Ring:PP" ctrlrange="0 1.5"/>
		<motor name="C:Ring:MPDP" joint="Ring:MP" ctrlrange="0 1.65"/>

		<motor name="C:Index:AP" joint="Index:AP" ctrlrange="0 0.95"/>
		<motor name="C:Index:PP" joint="Index:PP" ctrlrange="0 1.515"/>
		<motor name="C:Index:MPDP" joint="Index:MP" ctrlrange="0 1.6"/>

		<motor name="C:Thumb:AP" joint="Thumb:AP" ctrlrange="0 2.25"/>
		<motor name="C:Thumb:PP" joint="Thumb:PP" ctrlrange="0 1.575"/>
		<motor name="C:Thumb:MPDP" joint="Thumb:MP" ctrlrange="0 1.4"/>

		<motor name="C:Pinky:AP" joint="Pinky:AP" ctrlrange="0 0.95"/>
		<motor name="C:Pinky:PP" joint="Pinky:PP" ctrlrange="0 1.6"/>
		<motor name="C:Pinky:MPDP" joint="Pinky:MP" ctrlrange="0 1.65"/>


		<!-- <position name="C:Middle:AP" joint="Middle:AP" kp="1" kv="0.1" ctrlrange="0 0.95"/>
		<position name="C:Middle:PP" joint="Middle:PP" kp="1" kv="0.1" ctrlrange="0 1.5"/>
		<position name="C:Middle:MPDP" joint="Middle:MP" kp="1" kv="0.1" ctrlrange="0 1.65"/>

		<position name="C:Ring:AP" joint="Ring:AP" kp="1" kv="0.1" ctrlrange="0 0.95"/>
		<position name="C:Ring:PP" joint="Ring:PP" kp="1" kv="0.1" ctrlrange="0 1.5"/>
		<position name="C:Ring:MPDP" joint="Ring:MP" kp="1" kv="0.1" ctrlrange="0 1.65"/>

		<position name="C:Index:AP" joint="Index:AP" kp="1" kv="0.1" ctrlrange="0 0.95"/>
		<position name="C:Index:PP" joint="Index:PP" kp="1" kv="0.1" ctrlrange="0 1.515"/>
		<position name="C:Index:MPDP" joint="Index:MP" kp="1" kv="0.1" ctrlrange="0 1.6"/>

		<position name="C:Thumb:AP" joint="Thumb:AP" kp="1" kv="0.1" ctrlrange="0 2.25"/>
		<position name="C:Thumb:PP" joint="Thumb:PP" kp="1" kv="0.1" ctrlrange="0 1.575"/>
		<position name="C:Thumb:MPDP" joint="Thumb:MP" kp="1" kv="0.1" ctrlrange="0 1.4"/>

		<position name="C:Pinky:AP" joint="Pinky:AP" kp="1" kv="0.1" ctrlrange="0 0.95"/>
		<position name="C:Pinky:PP" joint="Pinky:PP" kp="1" kv="0.1" ctrlrange="0 1.6"/>
		<position name="C:Pinky:MPDP" joint="Pinky:MP" kp="1" kv="0.1" ctrlrange="0 1.65"/> -->
	</actuator>
	<contact>
		<!-- Manually added -->
		<exclude body1="Carpals:1/1" body2="M-AP:1/8"/>
		<exclude body1="Carpals:1/1" body2="M-AP:1/9"/>
		<exclude body1="Carpals:1/1" body2="M-AP:1/14"/>
		<exclude body1="Carpals:1/1" body2="T-AP:1/17"/>
		<exclude body1="Carpals:1/1" body2="M-AP:1/24"/>
		<!-- Manually added -->
		<!-- <exclude body1="M-AP:1/8" body2="M-PP:1/4"/>
		<exclude body1="M-PP:1/4" body2="M-MP:1/3"/>
		<exclude body1="M-MP:1/3" body2="M-DP:1/2"/>
		<exclude body1="M-AP:1/9" body2="M-PP:1/10"/>
		<exclude body1="M-PP:1/10" body2="M-MP:1/7"/>
		<exclude body1="M-MP:1/7" body2="M-DP:1/6"/>
		<exclude body1="M-AP:1/14" body2="I-PP:1/15"/>
		<exclude body1="I-PP:1/15" body2="M-MP:1/13"/>
		<exclude body1="M-MP:1/13" body2="M-DP:1/12"/>
		<exclude body1="T-AP:1/17" body2="T-AP_OUT:1/18"/>
		<exclude body1="T-AP_OUT:1/18" body2="T-PP:1/19"/>
		<exclude body1="T-PP:1/19" body2="T-DP:1/20"/>
		<exclude body1="M-AP:1/24" body2="P-PP:1/25"/>
		<exclude body1="P-PP:1/25" body2="M-MP:1/23"/>
		<exclude body1="M-MP:1/23" body2="M-DP:1/22"/> -->
	</contact>
	<equality>
		<!-- 0.58333 = 70/120 -->
        <joint joint1="Middle:MP" joint2="Middle:DP" polycoef="0 0.58333 0 0 0"/>
		<joint joint1="Ring:MP" joint2="Ring:DP" polycoef="0 0.58333 0 0 0"/>
		<joint joint1="Index:MP" joint2="Index:DP" polycoef="0 0.58333 0 0 0"/>
		<joint joint1="Thumb:MP" joint2="Thumb:DP" polycoef="0 0.58333 0 0 0"/>
		<joint joint1="Pinky:MP" joint2="Pinky:DP" polycoef="0 0.58333 0 0 0"/>
    </equality>
</mujoco>