<mujoco model="DexterousDynamos">
	<compiler angle="radian"/>
	<option integrator="RK4" timestep="0.0001"/>
	<default>
		<default class="collision">
			<geom contype="1" conaffinity="1" group="4"/>
		</default>
		<default class="visual">
			<geom contype="0" conaffinity="0" group="1" mass="0"/>
		</default>
		<geom type="mesh" quat="1 0 0 0"/>
		<position ctrllimited="true" kp="100"/>
		<velocity ctrllimited="true" kv="10"/>
		<motor ctrllimited="true"/>
		<mesh scale="0.001 0.001 0.001"/>
		<joint type="hinge" limited="true"/>
	</default>
	<asset>
		<mesh name="T-PP" file="/home/arturo/Documents/DexterousDynamos/old/mujoco/assets/fusion_export_2024-11-13_13-04-40/T-PP.stl"/>
		<mesh name="M-DP" file="/home/arturo/Documents/DexterousDynamos/old/mujoco/assets/fusion_export_2024-11-13_13-04-40/M-DP.stl"/>
		<mesh name="I-PP" file="/home/arturo/Documents/DexterousDynamos/old/mujoco/assets/fusion_export_2024-11-13_13-04-40/I-PP.stl"/>
		<mesh name="T-AP_OUT" file="/home/arturo/Documents/DexterousDynamos/old/mujoco/assets/fusion_export_2024-11-13_13-04-40/T-AP_OUT.stl"/>
		<mesh name="M-MP" file="/home/arturo/Documents/DexterousDynamos/old/mujoco/assets/fusion_export_2024-11-13_13-04-40/M-MP.stl"/>
		<mesh name="T-DP" file="/home/arturo/Documents/DexterousDynamos/old/mujoco/assets/fusion_export_2024-11-13_13-04-40/T-DP.stl"/>
		<mesh name="Carpals" file="/home/arturo/Documents/DexterousDynamos/old/mujoco/assets/fusion_export_2024-11-13_13-04-40/Carpals.stl"/>
		<mesh name="P-PP" file="/home/arturo/Documents/DexterousDynamos/old/mujoco/assets/fusion_export_2024-11-13_13-04-40/P-PP.stl"/>
		<mesh name="M-PP" file="/home/arturo/Documents/DexterousDynamos/old/mujoco/assets/fusion_export_2024-11-13_13-04-40/M-PP.stl"/>
		<mesh name="T-Assembly" file="/home/arturo/Documents/DexterousDynamos/old/mujoco/assets/fusion_export_2024-11-13_13-04-40/T-Assembly.stl"/>
		<mesh name="M-Assembly" file="/home/arturo/Documents/DexterousDynamos/old/mujoco/assets/fusion_export_2024-11-13_13-04-40/M-Assembly.stl"/>
		<mesh name="M-AP" file="/home/arturo/Documents/DexterousDynamos/old/mujoco/assets/fusion_export_2024-11-13_13-04-40/M-AP.stl"/>
		<mesh name="P-Assembly" file="/home/arturo/Documents/DexterousDynamos/old/mujoco/assets/fusion_export_2024-11-13_13-04-40/P-Assembly.stl"/>
		<mesh name="I-Assembly" file="/home/arturo/Documents/DexterousDynamos/old/mujoco/assets/fusion_export_2024-11-13_13-04-40/I-Assembly.stl"/>
		<mesh name="T-AP" file="/home/arturo/Documents/DexterousDynamos/old/mujoco/assets/fusion_export_2024-11-13_13-04-40/T-AP.stl"/>
	</asset>
	<worldbody>
		<body name="Carpals:1/1" pos="-0.00238190957064469 7.70089423848335e-05 0.04535823796707633" quat="0.9961946980917453 -4.326166003377961e-18 0.08715574274765808 -7.640172413512775e-17">
			<geom class="visual" mesh="Carpals"/>
			<geom class="collision" mesh="Carpals"/>
		</body>
		<body name="M-AP:1/8" pos="0.005936181919859313 7.700894238483996e-05 0.0980732193710854" quat="-0.45451947767204337 -0.4545194776720444 -0.5416752204197023 0.541675220419702">
			<joint name="Middle:AP" type="hinge" pos="0.015 0 0" axis="0 0 1" range="-0.4 0.55"/>
			<body name="M-PP:1/4" pos="-3.140053225544006e-17 1.8243278108651677e-17 1.9976425028045345e-17" quat="0.5372996083468242 -3.3306690738754696e-16 -0.8433914458128848 2.220446049250313e-16">
				<joint name="Middle:PP" type="hinge" pos="0 0 0" axis="0 1 0" range="-1.1 0.4"/>
				<body name="M-MP:1/3" pos="-5.898059818321144e-17 3.9898639947466563e-17 0.048000000000000126" quat="-0.9762960071199318 2.220446049250313e-16 0.21643961393810393 3.885780586188048e-16">
					<joint name="Middle:MP" type="hinge" pos="0 0 0" axis="0 1 0" range="-1.6 0.35"/>
					<body name="M-DP:1/2" pos="0.0010000000000000946 -0.0001000000000000046 0.02799999999999996" quat="-0.563324962600013 -0.4273932457488013 -0.4273932457488012 -0.5633249626000139">
						<joint name="Middle:DP" type="hinge" pos="0 0 0" axis="1 0 0" range="-1.35 0.3"/>
						<geom class="visual" mesh="M-DP"/>
						<geom class="collision" mesh="M-DP"/>
					</body>
					<geom class="visual" mesh="M-MP"/>
					<geom class="collision" mesh="M-MP"/>
				</body>
				<geom class="visual" mesh="M-PP"/>
				<geom class="collision" mesh="M-PP"/>
			</body>
			<geom class="visual" mesh="M-AP"/>
			<geom class="collision" mesh="M-AP"/>
		</body>
		<body name="M-AP:1/9" pos="0.02835383204857319 0.0022825334664441123 0.08512081153257114" quat="0.40230685029693486 0.35682632796897906 0.6166378107275328 -0.5749625903078316">
			<joint name="Ring:AP" type="hinge" pos="0.015 0 0" axis="0 0 1" range="-0.4 0.55"/>
			<body name="M-PP:1/10" pos="-1.0279336969361477e-17 2.2068836041567012e-17 3.5639619448738335e-19" quat="0.5372996083468238 3.885780586188048e-16 -0.8433914458128828 -3.3306690738754696e-16">
				<joint name="Ring:PP" type="hinge" pos="0 0 0" axis="0 1 0" range="-1.1 0.4"/>
				<body name="M-MP:1/7" pos="-1.1237755517812253e-16 -6.938893903907228e-17 0.048000000000000126" quat="-0.9848077530122077 -8.881784197001252e-16 0.17364817766693022 -6.661338147750939e-16">
					<joint name="Ring:MP" type="hinge" pos="0 0 0" axis="0 1 0" range="-1.6 0.3"/>
					<body name="M-DP:1/6" pos="0.001000000000000065 -9.99999999999994e-05 0.02799999999999988" quat="-0.551461606537142 -0.4425947316851787 -0.44259473168518043 -0.5514616065371394">
						<joint name="Ring:DP" type="hinge" pos="0 0 0" axis="1 0 0" range="-1.35 0.3"/>
						<geom class="visual" mesh="M-DP"/>
						<geom class="collision" mesh="M-DP"/>
					</body>
					<geom class="visual" mesh="M-MP"/>
					<geom class="collision" mesh="M-MP"/>
				</body>
				<geom class="visual" mesh="M-PP"/>
				<geom class="collision" mesh="M-PP"/>
			</body>
			<geom class="visual" mesh="M-AP"/>
			<geom class="collision" mesh="M-AP"/>
		</body>
		<body name="M-AP:1/14" pos="-0.019106237811017047 0.002252900976815083 0.09854638807338356" quat="0.49999999999999917 0.5416752204197021 0.4545194776720442 -0.5000000000000001">
			<joint name="Index:AP" type="hinge" pos="0.015 0 0" axis="0 0 1" range="-0.45 0.5"/>
			<body name="I-PP:1/15" pos="-5.582845235911708e-17 -1.2030992824632565e-18 -2.9507727956532246e-17" quat="-0.2588190451025195 -5.551115123125783e-17 0.9659258262890676 2.7755575615628914e-16">
				<joint name="Index:PP" type="hinge" pos="0 0 0" axis="0 1 0" range="-0.515 1"/>
				<body name="M-MP:1/13" pos="-6.765421556309548e-17 8.673617379884035e-17 0.04000000000000086" quat="0.8660254037844383 1.6653345369377348e-16 -0.4999999999999985 1.6653345369377348e-16">
					<joint name="Index:MP" type="hinge" pos="0 0 0" axis="0 1 0" range="-1 1"/>
					<body name="M-DP:1/12" pos="0.0009999999999999497 -0.0001000000000000445 0.028000000000000032" quat="0.6341847973991359 0.3127453320959722 0.3127453320959731 0.6341847973991364">
						<joint name="Index:DP" type="hinge" pos="0 0 0" axis="1 0 0" range="-0.9 0.7"/>
						<geom class="visual" mesh="M-DP"/>
						<geom class="collision" mesh="M-DP"/>
					</body>
					<geom class="visual" mesh="M-MP"/>
					<geom class="collision" mesh="M-MP"/>
				</body>
				<geom class="visual" mesh="I-PP"/>
				<geom class="collision" mesh="I-PP"/>
			</body>
			<geom class="visual" mesh="M-AP"/>
			<geom class="collision" mesh="M-AP"/>
		</body>
		<body name="T-AP:1/17" pos="-0.027853286536927657 0.018423718863623616 0.03447549918465962" quat="0.3852401358715211 -0.6338439601613196 0.637041107450773 0.2097867948623215">
			<joint name="Thumb:AP" type="hinge" pos="0.0175 0 0" axis="0 0 1" range="-1.5 0.75"/>
			<body name="T-AP_OUT:1/18" pos="-0.02265057831928084 1.1449174941446927e-15 0.0039939080863386454" quat="0.704416026402759 0.704416026402765 0.06162841671620575 -0.061628416716203255">
				<joint name="Thumb:PP" type="hinge" pos="0.023 0 0" axis="0 0 1" range="-1.4 1.75"/>
				<body name="T-PP:1/19" pos="1.3770912932280967e-15 1.0198011323983035e-16 8.958424040800124e-16" quat="-1.1102230246251565e-15 -0.6427876096865577 -1.0269562977782698e-15 0.7660444431189624">
					<joint name="Thumb:MP" type="hinge" pos="0 0 0" axis="0 1 0" range="-1.3 0.1"/>
					<body name="T-DP:1/20" pos="5.0187718564354e-16 4.3021142204224816e-16 0.029999999999999808" quat="0.6272113751262417 0.32650557562198035 0.3265055756219865 0.627211375126247">
						<joint name="Thumb:DP" type="hinge" pos="0 0 0" axis="1 0 0" range="-1 0.6"/>
						<geom class="visual" mesh="T-DP"/>
						<geom class="collision" mesh="T-DP"/>
					</body>
					<geom class="visual" mesh="T-PP"/>
					<geom class="collision" mesh="T-PP"/>
				</body>
				<geom class="visual" mesh="T-AP_OUT"/>
				<geom class="collision" mesh="T-AP_OUT"/>
			</body>
			<geom class="visual" mesh="T-AP"/>
			<geom class="collision" mesh="T-AP"/>
		</body>
		<body name="M-AP:1/24" pos="0.049468640722696654 0.009761841595827476 0.06347838118715589" quat="0.25026098332500013 0.07641128912197186 0.7209909801985277 -0.6416406795023898">
			<joint name="Pinky:AP" type="hinge" pos="0.015 0 0" axis="0 0 1" range="-0.4 0.55"/>
			<body name="P-PP:1/25" pos="5.363200161746298e-17 8.246874634145557e-17 -1.2031500145368831e-17" quat="0.5735764363510455 -1.3600232051658168e-15 -0.8191520442889932 1.6653345369377348e-16">
				<joint name="Pinky:PP" type="hinge" pos="0 0 0" axis="0 1 0" range="-1.2 0.4"/>
				<body name="M-MP:1/23" pos="7.112366251504909e-17 -2.3592239273284576e-16 0.03000000000000012" quat="-0.9848077530122057 -3.885780586188048e-16 0.17364817766692986 1.27675647831893e-15">
					<joint name="Pinky:MP" type="hinge" pos="0 0 0" axis="0 1 0" range="-1.6 0.3"/>
					<body name="M-DP:1/22" pos="0.0009999999999998636 -9.999999999978776e-05 0.027999999999999744" quat="-0.5514616065371413 -0.4425947316851766 -0.4425947316851796 -0.5514616065371429">
						<joint name="Pinky:DP" type="hinge" pos="0 0 0" axis="1 0 0" range="-1.35 0.3"/>
						<geom class="visual" mesh="M-DP"/>
						<geom class="collision" mesh="M-DP"/>
					</body>
					<geom class="visual" mesh="M-MP"/>
					<geom class="collision" mesh="M-MP"/>
				</body>
				<geom class="visual" mesh="P-PP"/>
				<geom class="collision" mesh="P-PP"/>
			</body>
			<geom class="visual" mesh="M-AP"/>
			<geom class="collision" mesh="M-AP"/>
		</body>
	</worldbody>
	<actuator>
		<!-- <motor name="C:Middle:AP" joint="Middle:AP" ctrlrange="-1 1"/>
		<motor name="C:Middle:PP" joint="Middle:PP" ctrlrange="-0.005 0.01"/>
		<motor name="C:Middle:MPDP" joint="Middle:MP" ctrlrange="-0.001 0.002"/> -->
		<motor name="C:Middle:AP" joint="Middle:AP" ctrlrange="-0.01 0.01"/>
		<motor name="C:Middle:PP" joint="Middle:PP" ctrlrange="-0.01 0.02"/>
		<motor name="C:Middle:MPDP" joint="Middle:MP" ctrlrange="-0.002 0.005"/>

		<motor name="C:Ring:AP" joint="Ring:AP" ctrlrange="-0.01 0.01"/>
		<motor name="C:Ring:PP" joint="Ring:PP" ctrlrange="-0.01 0.02"/>
		<motor name="C:Ring:MPDP" joint="Ring:MP" ctrlrange="-0.002 0.005"/>

		<motor name="C:Index:AP" joint="Index:AP" ctrlrange="-0.01 0.01"/>
		<motor name="C:Index:PP" joint="Index:PP" ctrlrange="-0.01 0.02"/>
		<motor name="C:Index:MPDP" joint="Index:MP" ctrlrange="-0.002 0.005"/>

		<motor name="C:Thumb:AP" joint="Thumb:AP" ctrlrange="-0.01 0.1"/>
		<motor name="C:Thumb:PP" joint="Thumb:PP" ctrlrange="-0.01 0.02"/>
		<motor name="C:Thumb:MPDP" joint="Thumb:MP" ctrlrange="-0.002 0.005"/>

		<motor name="C:Pinky:AP" joint="Pinky:AP" ctrlrange="-0.01 0.01"/>
		<motor name="C:Pinky:PP" joint="Pinky:PP" ctrlrange="-0.01 0.02"/>
		<motor name="C:Pinky:MPDP" joint="Pinky:MP" ctrlrange="-0.002 0.005"/>
	</actuator>
	<contact>
		<!-- Manually added -->
		<exclude body1="Carpals:1/1" body2="M-AP:1/8"/>
		<exclude body1="Carpals:1/1" body2="M-AP:1/9"/>
		<exclude body1="Carpals:1/1" body2="M-AP:1/14"/>
		<exclude body1="Carpals:1/1" body2="T-AP:1/17"/>
		<exclude body1="Carpals:1/1" body2="M-AP:1/24"/>
		<!-- Manually added -->
		<exclude body1="M-AP:1/8" body2="M-PP:1/4"/>
		<exclude body1="M-PP:1/4" body2="M-MP:1/3"/>
		<exclude body1="M-MP:1/3" body2="M-DP:1/2"/>
		<exclude body1="M-AP:1/9" body2="M-PP:1/10"/>
		<exclude body1="M-PP:1/10" body2="M-MP:1/7"/>
		<exclude body1="M-MP:1/7" body2="M-DP:1/6"/>
		<exclude body1="M-AP:1/14" body2="I-PP:1/15"/>
		<exclude body1="I-PP:1/15" body2="M-MP:1/13"/>
		<exclude body1="M-MP:1/13" body2="M-DP:1/12"/>
		<exclude body1="T-AP:1/17" body2="T-AP_OUT:1/18"/>
		<exclude body1="T-AP_OUT:1/18" body2="T-PP:1/19"/>
		<exclude body1="T-PP:1/19" body2="T-DP:1/20"/>
		<exclude body1="M-AP:1/24" body2="P-PP:1/25"/>
		<exclude body1="P-PP:1/25" body2="M-MP:1/23"/>
		<exclude body1="M-MP:1/23" body2="M-DP:1/22"/>
	</contact>
	<equality>
		<!-- 0.58333 = 70/120 -->
        <joint joint1="Middle:MP" joint2="Middle:DP" polycoef="0 0.58333 0 0 0"/>
		<joint joint1="Ring:MP" joint2="Ring:DP" polycoef="0 0.58333 0 0 0"/>
		<joint joint1="Index:MP" joint2="Index:DP" polycoef="0 0.58333 0 0 0"/>
		<joint joint1="Thumb:MP" joint2="Thumb:DP" polycoef="0 0.58333 0 0 0"/>
		<joint joint1="Pinky:MP" joint2="Pinky:DP" polycoef="0 0.58333 0 0 0"/>
    </equality>
</mujoco>