<mujoco model="DexterousDynamos">
	<compiler angle="radian"/>
	<option integrator="RK4"/>
	<default>
		<default class="collision">
			<geom contype="1" conaffinity="1" group="4"/>
		</default>
		<default class="visual">
			<geom contype="0" conaffinity="0" group="1" mass="0"/>
		</default>
		<geom type="mesh" quat="1 0 0 0"/>
		<position ctrllimited="true" kp="100"/>
		<velocity ctrllimited="true" kv="10"/>
		<motor ctrllimited="true"/>
		<mesh scale="0.001 0.001 0.001"/>
		<joint type="hinge" limited="true"/>
	</default>
	<asset>
		<mesh name="T-PP" file="/home/arturo/Documents/DexterousDynamos/mujoco/assets/fusion_export_2024-11-14_21-01-59/T-PP.stl"/>
		<mesh name="M-DP" file="/home/arturo/Documents/DexterousDynamos/mujoco/assets/fusion_export_2024-11-14_21-01-59/M-DP.stl"/>
		<mesh name="I-PP" file="/home/arturo/Documents/DexterousDynamos/mujoco/assets/fusion_export_2024-11-14_21-01-59/I-PP.stl"/>
		<mesh name="T-AP_OUT" file="/home/arturo/Documents/DexterousDynamos/mujoco/assets/fusion_export_2024-11-14_21-01-59/T-AP_OUT.stl"/>
		<mesh name="M-MP" file="/home/arturo/Documents/DexterousDynamos/mujoco/assets/fusion_export_2024-11-14_21-01-59/M-MP.stl"/>
		<mesh name="T-DP" file="/home/arturo/Documents/DexterousDynamos/mujoco/assets/fusion_export_2024-11-14_21-01-59/T-DP.stl"/>
		<mesh name="Carpals" file="/home/arturo/Documents/DexterousDynamos/mujoco/assets/fusion_export_2024-11-14_21-01-59/Carpals.stl"/>
		<mesh name="P-PP" file="/home/arturo/Documents/DexterousDynamos/mujoco/assets/fusion_export_2024-11-14_21-01-59/P-PP.stl"/>
		<mesh name="M-PP" file="/home/arturo/Documents/DexterousDynamos/mujoco/assets/fusion_export_2024-11-14_21-01-59/M-PP.stl"/>
		<mesh name="T-Assembly" file="/home/arturo/Documents/DexterousDynamos/mujoco/assets/fusion_export_2024-11-14_21-01-59/T-Assembly.stl"/>
		<mesh name="M-Assembly" file="/home/arturo/Documents/DexterousDynamos/mujoco/assets/fusion_export_2024-11-14_21-01-59/M-Assembly.stl"/>
		<mesh name="M-AP" file="/home/arturo/Documents/DexterousDynamos/mujoco/assets/fusion_export_2024-11-14_21-01-59/M-AP.stl"/>
		<mesh name="P-Assembly" file="/home/arturo/Documents/DexterousDynamos/mujoco/assets/fusion_export_2024-11-14_21-01-59/P-Assembly.stl"/>
		<mesh name="I-Assembly" file="/home/arturo/Documents/DexterousDynamos/mujoco/assets/fusion_export_2024-11-14_21-01-59/I-Assembly.stl"/>
		<mesh name="T-AP" file="/home/arturo/Documents/DexterousDynamos/mujoco/assets/fusion_export_2024-11-14_21-01-59/T-AP.stl"/>
	</asset>
	<worldbody>
		<body name="01" pos="0.0 0.0 0.0" quat="1.0 0.0 0.0 0.0">
			<body name="19" pos="0.028872205457314275 0.0026874214663675125 0.04161740433078695" quat="0.3265055756219767 0.2705980500730984 0.6532814824381886 -0.6272113751262515">
				<body name="20" pos="-1.1690705480312684e-16 4.3671336227542125e-17 8.630645624194291e-18" quat="0.7660444431189766 3.3306690738754696e-16 -0.6427876096865381 1.1102230246251565e-16">
					<body name="21" pos="1.5612511283791264e-17 -2.0816681711721685e-17 0.048000000000000015" quat="0.9999999999999978 8.326672684688674e-17 3.0808688933348094e-15 -1.6653345369377348e-16">
						<body name="22" pos="0.0009999999999998656 -0.00010000000000006011 0.028000000000000084" quat="0.5000000000000037 0.4999999999999992 0.5 0.5000000000000006">
							<joint name="22_joint" pos="9.999999999998384e-05 1.4816977939730025e-16 3.064226389987157e-17" axis="-1.0 -2.3037127760972e-15 3.164135620181696e-15" range="-3.141592653589793 3.141592653589793"/>
							<geom class="visual" mesh="M-DP"/>
							<geom class="collision" mesh="M-DP"/>
						</body>
						<joint name="21_joint" pos="2.9045983519494986e-17 -4.561793484406721e-18 1.3229231474179587e-16" axis="7.216449660063518e-16 -1.0000000000000024 1.2490009027033011e-15" range="-3.141592653589793 3.141592653589793"/>
						<geom class="visual" mesh="M-MP"/>
						<geom class="collision" mesh="M-MP"/>
					</body>
					<joint name="20_joint" pos="6.06636806868828e-18 2.168039016970056e-17 2.752823464978104e-17" axis="-1.6653345369377348e-16 -1.0000000000000042 2.1649348980190553e-15" range="-3.141592653589793 3.141592653589793"/>
					<geom class="visual" mesh="M-PP"/>
					<geom class="collision" mesh="M-PP"/>
				</body>
				<joint name="19_joint" pos="0.07787979451597131 0.040781045359604834 0.0011284469815615143" axis="0.05602263155122228 -0.06676517241774882 0.9961946980917438" range="-3.141592653589793 3.141592653589793"/>
				<geom class="visual" mesh="M-AP"/>
				<geom class="collision" mesh="M-AP"/>
			</body>
			<body name="23" pos="0.047916294077601604 0.009684832653442693 0.026848611098292226" quat="0.31214716912115686 0.13204319109680737 0.696435709963295 -0.6325393603425353">
				<body name="24" pos="3.3689711733889896e-16 4.79020458533684e-17 -5.4767624688648634e-17" quat="0.7660444431189763 -4.440892098500626e-16 -0.6427876096865404 0.0">
					<body name="25" pos="9.107298248878237e-17 -5.637851296924623e-17 0.029999999999999975" quat="0.9999999999999973 5.828670879282072e-16 4.274358644806853e-15 -4.440892098500626e-16">
						<body name="26" pos="0.000999999999999948 -0.00010000000000002542 0.02800000000000011" quat="0.500000000000003 0.49999999999999817 0.5000000000000002 0.5000000000000011">
							<joint name="26_joint" pos="9.999999999999823e-05 1.5554235417020168e-16 -6.428641256481238e-17" axis="-1.0000000000000036 -3.4416913763379853e-15 9.71445146547012e-16" range="-3.141592653589793 3.141592653589793"/>
							<geom class="visual" mesh="M-DP"/>
							<geom class="collision" mesh="M-DP"/>
						</body>
						<joint name="25_joint" pos="-2.7843967589593596e-17 -2.693709667477075e-17 3.1856746247216845e-17" axis="7.771561172376096e-16 -1.0000000000000033 3.3306690738754696e-16" range="-3.141592653589793 3.141592653589793"/>
						<geom class="visual" mesh="M-MP"/>
						<geom class="collision" mesh="M-MP"/>
					</body>
					<joint name="24_joint" pos="-1.314518243859969e-18 -1.2258146565428944e-17 -2.4927718063633906e-17" axis="-1.3322676295501878e-15 -1.0000000000000024 -2.498001805406602e-16" range="-3.141592653589793 3.141592653589793"/>
					<geom class="visual" mesh="P-PP"/>
					<geom class="collision" mesh="P-PP"/>
				</body>
				<joint name="23_joint" pos="0.014400000000000138 -6.418476861114186e-17 -0.0005000000000000167" axis="-2.706168622523819e-16 -7.216449660063518e-16 0.9999999999999971" range="-3.141592653589793 3.141592653589793"/>
				<geom class="visual" mesh="M-AP"/>
				<geom class="collision" mesh="M-AP"/>
			</body>
			<body name="07" pos="-0.03438778677666598 0.00830507569081303 -0.035012156902848916" quat="-0.410137020146706 0.8820758153862192 0.07296349761445203 0.22001411007430002">
				<body name="08" pos="-0.01626345596729065 1.0512424264419451e-15 0.016263455967290896" quat="0.6532814824381884 0.653281482438197 0.2705980500730959 -0.2705980500730881">
					<body name="09" pos="1.2710348209084786e-15 1.901726345105347e-16 9.2922765574284e-16" quat="1.1934897514720433e-15 -0.7660444431189752 -3.3861802251067274e-15 0.6427876096865379">
						<body name="10" pos="4.766152750246277e-16 3.7643499428696714e-16 0.030000000000000002" quat="0.4999999999999937 0.5000000000000095 0.4999999999999981 0.4999999999999997">
							<joint name="10_joint" pos="5.251839153662478e-17 -3.3899982038590286e-17 -1.0247425610677036e-16" axis="1.0000000000000233 -7.022160630754115e-15 -7.542577673547157e-15" range="-3.141592653589793 3.141592653589793"/>
							<geom class="visual" mesh="T-DP"/>
							<geom class="collision" mesh="T-DP"/>
						</body>
						<joint name="09_joint" pos="-6.706978609188035e-17 4.145740383238442e-17 2.0101342275670026e-17" axis="-2.1649348980190553e-15 0.9999999999999918 1.0130785099704553e-14" range="-3.141592653589793 3.141592653589793"/>
						<geom class="visual" mesh="T-PP"/>
						<geom class="collision" mesh="T-PP"/>
					</body>
					<joint name="08_joint" pos="0.023000000000000815 8.586881206085195e-17 7.658804146437603e-16" axis="-9.06219543850284e-15 -2.609024107869118e-15 0.9999999999999898" range="-3.141592653589793 3.141592653589793"/>
					<geom class="visual" mesh="T-AP_OUT"/>
					<geom class="collision" mesh="T-AP_OUT"/>
				</body>
				<joint name="07_joint" pos="0.01690000000000071 3.7578447298347584e-16 -9.999999999972767e-05" axis="5.028963356856764e-15 1.0436096431476471e-14 0.9999999999999584" range="-3.141592653589793 3.141592653589793"/>
				<geom class="visual" mesh="T-AP"/>
				<geom class="collision" mesh="T-AP"/>
			</body>
			<body name="11" pos="-0.018279794332525433 0.0015361038937075063 0.049471102826037235" quat="-0.402691056740765 -0.45740820860392006 -0.5462096196996411 0.5746935660596334">
				<body name="12" pos="5.150136399827679e-16 -5.3645723691710045e-17 1.7467264640023975e-18" quat="0.7660444431189807 -5.551115123125783e-16 -0.6427876096865364 -3.3306690738754696e-16">
					<body name="13" pos="-3.382710778154774e-16 3.9898639947466563e-17 0.03999999999999958" quat="0.9999999999999999 4.0245584642661925e-16 -7.424616477180734e-16 -2.220446049250313e-16">
						<body name="14" pos="0.0009999999999998127 -0.00010000000000014511 0.027999999999999386" quat="0.5000000000000014 0.4999999999999982 0.49999999999999734 0.5000000000000033">
							<joint name="14_joint" pos="0.00010000000000006439 1.0318047143683534e-16 -1.70772006561834e-16" axis="-0.999999999999992 4.593547764386585e-15 -1.8457457784393227e-15" range="-3.141592653589793 3.141592653589793"/>
							<geom class="visual" mesh="M-DP"/>
							<geom class="collision" mesh="M-DP"/>
						</body>
						<joint name="13_joint" pos="-7.810810969909062e-17 5.403498019402772e-17 1.1813061104453064e-17" axis="-5.551115123125783e-16 -0.9999999999999931 1.2906342661267445e-15" range="-3.141592653589793 3.141592653589793"/>
						<geom class="visual" mesh="M-MP"/>
						<geom class="collision" mesh="M-MP"/>
					</body>
					<joint name="12_joint" pos="-6.619303202950831e-19 1.1066244331047344e-17 5.123163855369711e-18" axis="-1.27675647831893e-15 -0.9999999999999905 -5.134781488891349e-16" range="-3.141592653589793 3.141592653589793"/>
					<geom class="visual" mesh="I-PP"/>
					<geom class="collision" mesh="I-PP"/>
				</body>
				<joint name="11_joint" pos="0.014400000000001186 -1.2533377113932431e-16 0.0005000000000000338" axis="-2.525757381022231e-15 -1.3322676295501878e-15 0.999999999999989" range="-3.141592653589793 3.141592653589793"/>
				<geom class="visual" mesh="M-AP"/>
				<geom class="collision" mesh="M-AP"/>
			</body>
			<body name="15" pos="0.005123563502627037 5.494914855853194e-18 0.05200937594888335" quat="-0.37992819659091526 -0.3799281965909158 -0.5963678105290183 0.5963678105290187">
				<body name="16" pos="1.8843021096399572e-16 9.382154005942786e-17 -2.640032290002196e-17" quat="0.7660444431189772 -4.440892098500626e-16 -0.6427876096865388 -6.106226635438361e-16">
					<body name="17" pos="-4.5102810375396984e-17 -8.673617379884035e-19 0.04800000000000042" quat="0.9999999999999979 5.551115123125783e-17 2.706168622523819e-15 1.1102230246251565e-16">
						<body name="18" pos="0.0009999999999998526 -0.00010000000000001284 0.02799999999999979" quat="0.5000000000000026 0.5000000000000002 0.49999999999999967 0.5000000000000034">
							<joint name="18_joint" pos="9.999999999998798e-05 9.637879687038331e-17 -3.9981649176297485e-17" axis="-1.0 1.1934897514720433e-15 2.914335439641036e-16" range="-3.141592653589793 3.141592653589793"/>
							<geom class="visual" mesh="M-DP"/>
							<geom class="collision" mesh="M-DP"/>
						</body>
						<joint name="17_joint" pos="-3.781721096192552e-18 1.7052027379470164e-17 1.1457331749829444e-17" axis="6.106226635438361e-16 -1.0000000000000024 1.3877787807814457e-17" range="-3.141592653589793 3.141592653589793"/>
						<geom class="visual" mesh="M-MP"/>
						<geom class="collision" mesh="M-MP"/>
					</body>
					<joint name="16_joint" pos="-8.71116903550488e-18 -2.264166457971279e-18 -7.195786959359214e-17" axis="8.881784197001252e-16 -1.0 -1.2351231148954867e-15" range="-3.141592653589793 3.141592653589793"/>
					<geom class="visual" mesh="M-PP"/>
					<geom class="collision" mesh="M-PP"/>
				</body>
				<joint name="15_joint" pos="0.014400000000000183 5.0306980803327406e-17 1.2576745200831851e-17" axis="-4.996003610813204e-16 4.440892098500626e-16 0.9999999999999983" range="-3.141592653589793 3.141592653589793"/>
				<geom class="visual" mesh="M-AP"/>
				<geom class="collision" mesh="M-AP"/>
			</body>
			<geom class="visual" mesh="Carpals"/>
			<geom class="collision" mesh="Carpals"/>
		</body>
	</worldbody>
	<actuator>
		<position name="15_joint_actuator" joint="15_joint" ctrlrange="-3.141592653589793 3.141592653589793"/>
		<position name="16_joint_actuator" joint="16_joint" ctrlrange="-3.141592653589793 3.141592653589793"/>
		<position name="17_joint_actuator" joint="17_joint" ctrlrange="-3.141592653589793 3.141592653589793"/>
		<position name="18_joint_actuator" joint="18_joint" ctrlrange="-3.141592653589793 3.141592653589793"/>
		<position name="11_joint_actuator" joint="11_joint" ctrlrange="-3.141592653589793 3.141592653589793"/>
		<position name="12_joint_actuator" joint="12_joint" ctrlrange="-3.141592653589793 3.141592653589793"/>
		<position name="13_joint_actuator" joint="13_joint" ctrlrange="-3.141592653589793 3.141592653589793"/>
		<position name="14_joint_actuator" joint="14_joint" ctrlrange="-3.141592653589793 3.141592653589793"/>
		<position name="07_joint_actuator" joint="07_joint" ctrlrange="-3.141592653589793 3.141592653589793"/>
		<position name="08_joint_actuator" joint="08_joint" ctrlrange="-3.141592653589793 3.141592653589793"/>
		<position name="09_joint_actuator" joint="09_joint" ctrlrange="-3.141592653589793 3.141592653589793"/>
		<position name="10_joint_actuator" joint="10_joint" ctrlrange="-3.141592653589793 3.141592653589793"/>
		<position name="23_joint_actuator" joint="23_joint" ctrlrange="-3.141592653589793 3.141592653589793"/>
		<position name="24_joint_actuator" joint="24_joint" ctrlrange="-3.141592653589793 3.141592653589793"/>
		<position name="25_joint_actuator" joint="25_joint" ctrlrange="-3.141592653589793 3.141592653589793"/>
		<position name="26_joint_actuator" joint="26_joint" ctrlrange="-3.141592653589793 3.141592653589793"/>
		<position name="19_joint_actuator" joint="19_joint" ctrlrange="-3.141592653589793 3.141592653589793"/>
		<position name="20_joint_actuator" joint="20_joint" ctrlrange="-3.141592653589793 3.141592653589793"/>
		<position name="21_joint_actuator" joint="21_joint" ctrlrange="-3.141592653589793 3.141592653589793"/>
		<position name="22_joint_actuator" joint="22_joint" ctrlrange="-3.141592653589793 3.141592653589793"/>
	</actuator>
	<contact>
		<exclude body1="01" body2="15"/>
		<exclude body1="15" body2="16"/>
		<exclude body1="16" body2="17"/>
		<exclude body1="17" body2="18"/>
		<exclude body1="01" body2="11"/>
		<exclude body1="11" body2="12"/>
		<exclude body1="12" body2="13"/>
		<exclude body1="13" body2="14"/>
		<exclude body1="01" body2="07"/>
		<exclude body1="07" body2="08"/>
		<exclude body1="08" body2="09"/>
		<exclude body1="09" body2="10"/>
		<exclude body1="01" body2="23"/>
		<exclude body1="23" body2="24"/>
		<exclude body1="24" body2="25"/>
		<exclude body1="25" body2="26"/>
		<exclude body1="01" body2="19"/>
		<exclude body1="19" body2="20"/>
		<exclude body1="20" body2="21"/>
		<exclude body1="21" body2="22"/>
	</contact>
	<equality>
	</equality>
</mujoco>